Workbook

Sheet Visión General
A1: Visión General 2026
A2: Categoría | B2: Tipo | C2: Enero | D2: Febrero | E2: Marzo | F2: Abril | G2: Mayo | H2: Junio | I2: Julio | J2: Agosto | K2: Septiembre | L2: Octubre | M2: Noviembre | N2: Diciembre | O2: Total | P2: % del año | Q2: Categoría
A3: =Categorías!A2 -> Videojuegos | B3: =Categorías!B2 -> Ocio | C3: =SUMIF(Enero!$C$3:$C$32,$A3,Enero!$E$3:$E$32) -> 0 | D3: =SUMIF(Febrero!$C$3:$C$32,$A3,Febrero!$E$3:$E$32) -> 0 | E3: =SUMIF(Marzo!$C$3:$C$32,$A3,Marzo!$E$3:$E$32) -> 0 | F3: =SUMIF(Abril!$C$3:$C$32,$A3,Abril!$E$3:$E$32) -> 0 | G3: =SUMIF(Mayo!$C$3:$C$32,$A3,Mayo!$E$3:$E$32) -> 0 | H3: =SUMIF(Junio!$C$3:$C$32,$A3,Junio!$E$3:$E$32) -> 0 | I3: =SUMIF(Julio!$C$3:$C$32,$A3,Julio!$E$3:$E$32) -> 40 | J3: =SUMIF(Agosto!$C$3:$C$32,$A3,Agosto!$E$3:$E$32) -> 0 | K3: =SUMIF(Septiembre!$C$3:$C$32,$A3,Septiembre!$E$3:$E$32) -> 0 | L3: =SUMIF(Octubre!$C$3:$C$32,$A3,Octubre!$E$3:$E$32) -> 0 | M3: =SUMIF(Noviembre!$C$3:$C$32,$A3,Noviembre!$E$3:$E$32) -> 0 | N3: =SUMIF(Diciembre!$C$3:$C$32,$A3,Diciembre!$E$3:$E$32) -> 0 | O3: =SUM(C3:N3) -> 40 | P3: =IFERROR(O3/$O$20,0) -> 0 | Q3: Videojuegos
A4: =Categorías!A3 -> Apuestas | B4: =Categorías!B3 -> Ocio | C4: =SUMIF(Enero!$C$3:$C$32,$A4,Enero!$E$3:$E$32) -> 0 | D4: =SUMIF(Febrero!$C$3:$C$32,$A4,Febrero!$E$3:$E$32) -> 0 | E4: =SUMIF(Marzo!$C$3:$C$32,$A4,Marzo!$E$3:$E$32) -> 0 | F4: =SUMIF(Abril!$C$3:$C$32,$A4,Abril!$E$3:$E$32) -> 0 | G4: =SUMIF(Mayo!$C$3:$C$32,$A4,Mayo!$E$3:$E$32) -> 0 | H4: =SUMIF(Junio!$C$3:$C$32,$A4,Junio!$E$3:$E$32) -> 0 | I4: =SUMIF(Julio!$C$3:$C$32,$A4,Julio!$E$3:$E$32) -> 40 | J4: =SUMIF(Agosto!$C$3:$C$32,$A4,Agosto!$E$3:$E$32) -> 0 | K4: =SUMIF(Septiembre!$C$3:$C$32,$A4,Septiembre!$E$3:$E$32) -> 0 | L4: =SUMIF(Octubre!$C$3:$C$32,$A4,Octubre!$E$3:$E$32) -> 0 | M4: =SUMIF(Noviembre!$C$3:$C$32,$A4,Noviembre!$E$3:$E$32) -> 0 | N4: =SUMIF(Diciembre!$C$3:$C$32,$A4,Diciembre!$E$3:$E$32) -> 0 | O4: =SUM(C4:N4) -> 40 | P4: =IFERROR(O4/$O$20,0) -> 0 | Q4: Apuestas
A5: =Categorías!A4 -> Salidas/Ocio | B5: =Categorías!B4 -> Ocio | C5: =SUMIF(Enero!$C$3:$C$32,$A5,Enero!$E$3:$E$32) -> 0 | D5: =SUMIF(Febrero!$C$3:$C$32,$A5,Febrero!$E$3:$E$32) -> 0 | E5: =SUMIF(Marzo!$C$3:$C$32,$A5,Marzo!$E$3:$E$32) -> 0 | F5: =SUMIF(Abril!$C$3:$C$32,$A5,Abril!$E$3:$E$32) -> 0 | G5: =SUMIF(Mayo!$C$3:$C$32,$A5,Mayo!$E$3:$E$32) -> 0 | H5: =SUMIF(Junio!$C$3:$C$32,$A5,Junio!$E$3:$E$32) -> 0 | I5: =SUMIF(Julio!$C$3:$C$32,$A5,Julio!$E$3:$E$32) -> 122.4 | J5: =SUMIF(Agosto!$C$3:$C$32,$A5,Agosto!$E$3:$E$32) -> 25.25 | K5: =SUMIF(Septiembre!$C$3:$C$32,$A5,Septiembre!$E$3:$E$32) -> 12.5 | L5: =SUMIF(Octubre!$C$3:$C$32,$A5,Octubre!$E$3:$E$32) -> 0 | M5: =SUMIF(Noviembre!$C$3:$C$32,$A5,Noviembre!$E$3:$E$32) -> 0 | N5: =SUMIF(Diciembre!$C$3:$C$32,$A5,Diciembre!$E$3:$E$32) -> 0 | O5: =SUM(C5:N5) -> 160.15 | P5: =IFERROR(O5/$O$20,0) -> 0 | Q5: Salidas/Ocio
A6: =Categorías!A5 -> Suscripciones ocio | B6: =Categorías!B5 -> Ocio | C6: =SUMIF(Enero!$C$3:$C$32,$A6,Enero!$E$3:$E$32) -> 0 | D6: =SUMIF(Febrero!$C$3:$C$32,$A6,Febrero!$E$3:$E$32) -> 0 | E6: =SUMIF(Marzo!$C$3:$C$32,$A6,Marzo!$E$3:$E$32) -> 0 | F6: =SUMIF(Abril!$C$3:$C$32,$A6,Abril!$E$3:$E$32) -> 0 | G6: =SUMIF(Mayo!$C$3:$C$32,$A6,Mayo!$E$3:$E$32) -> 0 | H6: =SUMIF(Junio!$C$3:$C$32,$A6,Junio!$E$3:$E$32) -> 0 | I6: =SUMIF(Julio!$C$3:$C$32,$A6,Julio!$E$3:$E$32) -> 8.5 | J6: =SUMIF(Agosto!$C$3:$C$32,$A6,Agosto!$E$3:$E$32) -> 11 | K6: =SUMIF(Septiembre!$C$3:$C$32,$A6,Septiembre!$E$3:$E$32) -> 8.5 | L6: =SUMIF(Octubre!$C$3:$C$32,$A6,Octubre!$E$3:$E$32) -> 0 | M6: =SUMIF(Noviembre!$C$3:$C$32,$A6,Noviembre!$E$3:$E$32) -> 0 | N6: =SUMIF(Diciembre!$C$3:$C$32,$A6,Diciembre!$E$3:$E$32) -> 0 | O6: =SUM(C6:N6) -> 28 | P6: =IFERROR(O6/$O$20,0) -> 0 | Q6: Suscripciones ocio
A7: =Categorías!A6 -> Viajes | B7: =Categorías!B6 -> Ocio | C7: =SUMIF(Enero!$C$3:$C$32,$A7,Enero!$E$3:$E$32) -> 0 | D7: =SUMIF(Febrero!$C$3:$C$32,$A7,Febrero!$E$3:$E$32) -> 0 | E7: =SUMIF(Marzo!$C$3:$C$32,$A7,Marzo!$E$3:$E$32) -> 0 | F7: =SUMIF(Abril!$C$3:$C$32,$A7,Abril!$E$3:$E$32) -> 0 | G7: =SUMIF(Mayo!$C$3:$C$32,$A7,Mayo!$E$3:$E$32) -> 0 | H7: =SUMIF(Junio!$C$3:$C$32,$A7,Junio!$E$3:$E$32) -> 0 | I7: =SUMIF(Julio!$C$3:$C$32,$A7,Julio!$E$3:$E$32) -> 0 | J7: =SUMIF(Agosto!$C$3:$C$32,$A7,Agosto!$E$3:$E$32) -> 0 | K7: =SUMIF(Septiembre!$C$3:$C$32,$A7,Septiembre!$E$3:$E$32) -> 0 | L7: =SUMIF(Octubre!$C$3:$C$32,$A7,Octubre!$E$3:$E$32) -> 0 | M7: =SUMIF(Noviembre!$C$3:$C$32,$A7,Noviembre!$E$3:$E$32) -> 0 | N7: =SUMIF(Diciembre!$C$3:$C$32,$A7,Diciembre!$E$3:$E$32) -> 0 | O7: =SUM(C7:N7) -> 0 | P7: =IFERROR(O7/$O$20,0) -> 0 | Q7: Viajes
A8: =Categorías!A7 -> Padel | B8: =Categorías!B7 -> Ocio | C8: =SUMIF(Enero!$C$3:$C$32,$A8,Enero!$E$3:$E$32) -> 0 | D8: =SUMIF(Febrero!$C$3:$C$32,$A8,Febrero!$E$3:$E$32) -> 0 | E8: =SUMIF(Marzo!$C$3:$C$32,$A8,Marzo!$E$3:$E$32) -> 0 | F8: =SUMIF(Abril!$C$3:$C$32,$A8,Abril!$E$3:$E$32) -> 0 | G8: =SUMIF(Mayo!$C$3:$C$32,$A8,Mayo!$E$3:$E$32) -> 0 | H8: =SUMIF(Junio!$C$3:$C$32,$A8,Junio!$E$3:$E$32) -> 0 | I8: =SUMIF(Julio!$C$3:$C$32,$A8,Julio!$E$3:$E$32) -> 15.96 | J8: =SUMIF(Agosto!$C$3:$C$32,$A8,Agosto!$E$3:$E$32) -> 12.3 | K8: =SUMIF(Septiembre!$C$3:$C$32,$A8,Septiembre!$E$3:$E$32) -> 36.95 | L8: =SUMIF(Octubre!$C$3:$C$32,$A8,Octubre!$E$3:$E$32) -> 0 | M8: =SUMIF(Noviembre!$C$3:$C$32,$A8,Noviembre!$E$3:$E$32) -> 0 | N8: =SUMIF(Diciembre!$C$3:$C$32,$A8,Diciembre!$E$3:$E$32) -> 0 | O8: =SUM(C8:N8) -> 65.21 | P8: =IFERROR(O8/$O$20,0) -> 0 | Q8: Padel
A9: =Categorías!A8 -> Alimentación | B9: =Categorías!B8 -> Ocio | C9: =SUMIF(Enero!$C$3:$C$32,$A9,Enero!$E$3:$E$32) -> 0 | D9: =SUMIF(Febrero!$C$3:$C$32,$A9,Febrero!$E$3:$E$32) -> 0 | E9: =SUMIF(Marzo!$C$3:$C$32,$A9,Marzo!$E$3:$E$32) -> 0 | F9: =SUMIF(Abril!$C$3:$C$32,$A9,Abril!$E$3:$E$32) -> 0 | G9: =SUMIF(Mayo!$C$3:$C$32,$A9,Mayo!$E$3:$E$32) -> 0 | H9: =SUMIF(Junio!$C$3:$C$32,$A9,Junio!$E$3:$E$32) -> 0 | I9: =SUMIF(Julio!$C$3:$C$32,$A9,Julio!$E$3:$E$32) -> 14.8 | J9: =SUMIF(Agosto!$C$3:$C$32,$A9,Agosto!$E$3:$E$32) -> 21.6 | K9: =SUMIF(Septiembre!$C$3:$C$32,$A9,Septiembre!$E$3:$E$32) -> 1.89 | L9: =SUMIF(Octubre!$C$3:$C$32,$A9,Octubre!$E$3:$E$32) -> 0 | M9: =SUMIF(Noviembre!$C$3:$C$32,$A9,Noviembre!$E$3:$E$32) -> 0 | N9: =SUMIF(Diciembre!$C$3:$C$32,$A9,Diciembre!$E$3:$E$32) -> 0 | O9: =SUM(C9:N9) -> 38.29 | P9: =IFERROR(O9/$O$20,0) -> 0 | Q9: Alimentación
A10: =Categorías!A9 -> Barça | B10: =Categorías!B9 -> Ocio | C10: =SUMIF(Enero!$C$3:$C$32,$A10,Enero!$E$3:$E$32) -> 0 | D10: =SUMIF(Febrero!$C$3:$C$32,$A10,Febrero!$E$3:$E$32) -> 0 | E10: =SUMIF(Marzo!$C$3:$C$32,$A10,Marzo!$E$3:$E$32) -> 0 | F10: =SUMIF(Abril!$C$3:$C$32,$A10,Abril!$E$3:$E$32) -> 0 | G10: =SUMIF(Mayo!$C$3:$C$32,$A10,Mayo!$E$3:$E$32) -> 0 | H10: =SUMIF(Junio!$C$3:$C$32,$A10,Junio!$E$3:$E$32) -> 0 | I10: =SUMIF(Julio!$C$3:$C$32,$A10,Julio!$E$3:$E$32) -> 0 | J10: =SUMIF(Agosto!$C$3:$C$32,$A10,Agosto!$E$3:$E$32) -> 0 | K10: =SUMIF(Septiembre!$C$3:$C$32,$A10,Septiembre!$E$3:$E$32) -> 197 | L10: =SUMIF(Octubre!$C$3:$C$32,$A10,Octubre!$E$3:$E$32) -> 0 | M10: =SUMIF(Noviembre!$C$3:$C$32,$A10,Noviembre!$E$3:$E$32) -> 0 | N10: =SUMIF(Diciembre!$C$3:$C$32,$A10,Diciembre!$E$3:$E$32) -> 0 | O10: =SUM(C10:N10) -> 197 | P10: =IFERROR(O10/$O$20,0) -> 0 | Q10: Barça
A11: =Categorías!A10 -> Vivienda/Alquiler | B11: =Categorías!B10 -> Ordinario | C11: =SUMIF(Enero!$C$3:$C$32,$A11,Enero!$E$3:$E$32) -> 0 | D11: =SUMIF(Febrero!$C$3:$C$32,$A11,Febrero!$E$3:$E$32) -> 0 | E11: =SUMIF(Marzo!$C$3:$C$32,$A11,Marzo!$E$3:$E$32) -> 0 | F11: =SUMIF(Abril!$C$3:$C$32,$A11,Abril!$E$3:$E$32) -> 0 | G11: =SUMIF(Mayo!$C$3:$C$32,$A11,Mayo!$E$3:$E$32) -> 0 | H11: =SUMIF(Junio!$C$3:$C$32,$A11,Junio!$E$3:$E$32) -> 0 | I11: =SUMIF(Julio!$C$3:$C$32,$A11,Julio!$E$3:$E$32) -> 0 | J11: =SUMIF(Agosto!$C$3:$C$32,$A11,Agosto!$E$3:$E$32) -> 0 | K11: =SUMIF(Septiembre!$C$3:$C$32,$A11,Septiembre!$E$3:$E$32) -> 0 | L11: =SUMIF(Octubre!$C$3:$C$32,$A11,Octubre!$E$3:$E$32) -> 0 | M11: =SUMIF(Noviembre!$C$3:$C$32,$A11,Noviembre!$E$3:$E$32) -> 0 | N11: =SUMIF(Diciembre!$C$3:$C$32,$A11,Diciembre!$E$3:$E$32) -> 0 | O11: =SUM(C11:N11) -> 0 | P11: =IFERROR(O11/$O$20,0) -> 0 | Q11: Vivienda/Alquiler
A12: =Categorías!A11 -> Transporte | B12: =Categorías!B11 -> Ordinario | C12: =SUMIF(Enero!$C$3:$C$32,$A12,Enero!$E$3:$E$32) -> 0 | D12: =SUMIF(Febrero!$C$3:$C$32,$A12,Febrero!$E$3:$E$32) -> 0 | E12: =SUMIF(Marzo!$C$3:$C$32,$A12,Marzo!$E$3:$E$32) -> 0 | F12: =SUMIF(Abril!$C$3:$C$32,$A12,Abril!$E$3:$E$32) -> 0 | G12: =SUMIF(Mayo!$C$3:$C$32,$A12,Mayo!$E$3:$E$32) -> 0 | H12: =SUMIF(Junio!$C$3:$C$32,$A12,Junio!$E$3:$E$32) -> 0 | I12: =SUMIF(Julio!$C$3:$C$32,$A12,Julio!$E$3:$E$32) -> 0 | J12: =SUMIF(Agosto!$C$3:$C$32,$A12,Agosto!$E$3:$E$32) -> 0 | K12: =SUMIF(Septiembre!$C$3:$C$32,$A12,Septiembre!$E$3:$E$32) -> 13 | L12: =SUMIF(Octubre!$C$3:$C$32,$A12,Octubre!$E$3:$E$32) -> 0 | M12: =SUMIF(Noviembre!$C$3:$C$32,$A12,Noviembre!$E$3:$E$32) -> 0 | N12: =SUMIF(Diciembre!$C$3:$C$32,$A12,Diciembre!$E$3:$E$32) -> 0 | O12: =SUM(C12:N12) -> 13 | P12: =IFERROR(O12/$O$20,0) -> 0 | Q12: Transporte
A13: =Categorías!A12 -> Salud | B13: =Categorías!B12 -> Ordinario | C13: =SUMIF(Enero!$C$3:$C$32,$A13,Enero!$E$3:$E$32) -> 0 | D13: =SUMIF(Febrero!$C$3:$C$32,$A13,Febrero!$E$3:$E$32) -> 0 | E13: =SUMIF(Marzo!$C$3:$C$32,$A13,Marzo!$E$3:$E$32) -> 0 | F13: =SUMIF(Abril!$C$3:$C$32,$A13,Abril!$E$3:$E$32) -> 0 | G13: =SUMIF(Mayo!$C$3:$C$32,$A13,Mayo!$E$3:$E$32) -> 0 | H13: =SUMIF(Junio!$C$3:$C$32,$A13,Junio!$E$3:$E$32) -> 0 | I13: =SUMIF(Julio!$C$3:$C$32,$A13,Julio!$E$3:$E$32) -> 0 | J13: =SUMIF(Agosto!$C$3:$C$32,$A13,Agosto!$E$3:$E$32) -> 0 | K13: =SUMIF(Septiembre!$C$3:$C$32,$A13,Septiembre!$E$3:$E$32) -> 0 | L13: =SUMIF(Octubre!$C$3:$C$32,$A13,Octubre!$E$3:$E$32) -> 0 | M13: =SUMIF(Noviembre!$C$3:$C$32,$A13,Noviembre!$E$3:$E$32) -> 0 | N13: =SUMIF(Diciembre!$C$3:$C$32,$A13,Diciembre!$E$3:$E$32) -> 0 | O13: =SUM(C13:N13) -> 0 | P13: =IFERROR(O13/$O$20,0) -> 0 | Q13: Salud
A14: =Categorías!A13 -> Barbero | B14: =Categorías!B13 -> Ordinario | C14: =SUMIF(Enero!$C$3:$C$32,$A14,Enero!$E$3:$E$32) -> 0 | D14: =SUMIF(Febrero!$C$3:$C$32,$A14,Febrero!$E$3:$E$32) -> 0 | E14: =SUMIF(Marzo!$C$3:$C$32,$A14,Marzo!$E$3:$E$32) -> 0 | F14: =SUMIF(Abril!$C$3:$C$32,$A14,Abril!$E$3:$E$32) -> 0 | G14: =SUMIF(Mayo!$C$3:$C$32,$A14,Mayo!$E$3:$E$32) -> 0 | H14: =SUMIF(Junio!$C$3:$C$32,$A14,Junio!$E$3:$E$32) -> 0 | I14: =SUMIF(Julio!$C$3:$C$32,$A14,Julio!$E$3:$E$32) -> 15 | J14: =SUMIF(Agosto!$C$3:$C$32,$A14,Agosto!$E$3:$E$32) -> 0 | K14: =SUMIF(Septiembre!$C$3:$C$32,$A14,Septiembre!$E$3:$E$32) -> 15 | L14: =SUMIF(Octubre!$C$3:$C$32,$A14,Octubre!$E$3:$E$32) -> 0 | M14: =SUMIF(Noviembre!$C$3:$C$32,$A14,Noviembre!$E$3:$E$32) -> 0 | N14: =SUMIF(Diciembre!$C$3:$C$32,$A14,Diciembre!$E$3:$E$32) -> 0 | O14: =SUM(C14:N14) -> 30 | P14: =IFERROR(O14/$O$20,0) -> 0 | Q14: Barbero
... A18: =Categorías!A17 -> Multas | B18: =Categorías!B17 -> Extraordinario Evitable | C18: =SUMIF(Enero!$C$3:$C$32,$A18,Enero!$E$3:$E$32) -> 0 | D18: =SUMIF(Febrero!$C$3:$C$32,$A18,Febrero!$E$3:$E$32) -> 0 | E18: =SUMIF(Marzo!$C$3:$C$32,$A18,Marzo!$E$3:$E$32) -> 0 | F18: =SUMIF(Abril!$C$3:$C$32,$A18,Abril!$E$3:$E$32) -> 0 | G18: =SUMIF(Mayo!$C$3:$C$32,$A18,Mayo!$E$3:$E$32) -> 0 | H18: =SUMIF(Junio!$C$3:$C$32,$A18,Junio!$E$3:$E$32) -> 0 | I18: =SUMIF(Julio!$C$3:$C$32,$A18,Julio!$E$3:$E$32) -> 50 | J18: =SUMIF(Agosto!$C$3:$C$32,$A18,Agosto!$E$3:$E$32) -> 0 | K18: =SUMIF(Septiembre!$C$3:$C$32,$A18,Septiembre!$E$3:$E$32) -> 0 | L18: =SUMIF(Octubre!$C$3:$C$32,$A18,Octubre!$E$3:$E$32) -> 0 | M18: =SUMIF(Noviembre!$C$3:$C$32,$A18,Noviembre!$E$3:$E$32) -> 0 | N18: =SUMIF(Diciembre!$C$3:$C$32,$A18,Diciembre!$E$3:$E$32) -> 0 | O18: =SUM(C18:N18) -> 50 | P18: =IFERROR(O18/$O$20,0) -> 0 | Q18: Multas
A19: =Categorías!A18 -> Otros extraordinarios | B19: =Categorías!B18 -> Extraordinario Inevitable | C19: =SUMIF(Enero!$C$3:$C$32,$A19,Enero!$E$3:$E$32) -> 0 | D19: =SUMIF(Febrero!$C$3:$C$32,$A19,Febrero!$E$3:$E$32) -> 0 | E19: =SUMIF(Marzo!$C$3:$C$32,$A19,Marzo!$E$3:$E$32) -> 0 | F19: =SUMIF(Abril!$C$3:$C$32,$A19,Abril!$E$3:$E$32) -> 0 | G19: =SUMIF(Mayo!$C$3:$C$32,$A19,Mayo!$E$3:$E$32) -> 0 | H19: =SUMIF(Junio!$C$3:$C$32,$A19,Junio!$E$3:$E$32) -> 0 | I19: =SUMIF(Julio!$C$3:$C$32,$A19,Julio!$E$3:$E$32) -> 0 | J19: =SUMIF(Agosto!$C$3:$C$32,$A19,Agosto!$E$3:$E$32) -> 0 | K19: =SUMIF(Septiembre!$C$3:$C$32,$A19,Septiembre!$E$3:$E$32) -> 0 | L19: =SUMIF(Octubre!$C$3:$C$32,$A19,Octubre!$E$3:$E$32) -> 0 | M19: =SUMIF(Noviembre!$C$3:$C$32,$A19,Noviembre!$E$3:$E$32) -> 0 | N19: =SUMIF(Diciembre!$C$3:$C$32,$A19,Diciembre!$E$3:$E$32) -> 0 | O19: =SUM(C19:N19) -> 0 | P19: =IFERROR(O19/$O$21,0) -> 0 | Q19: Otros extraordinarios
A21: TOTAL | C21: =SUM(C3:C19) -> 0 | D21: =SUM(D3:D19) -> 0 | E21: =SUM(E3:E19) -> 0 | F21: =SUM(F3:F19) -> 0 | G21: =SUM(G3:G19) -> 0 | H21: =SUM(H3:H19) -> 0 | I21: =SUM(I3:I19) -> 563.96 | J21: =SUM(J3:J19) -> 76.5 | ... O21: =SUM(O3:O19) -> 925.3
A23: Total Ocio | C23: =SUMIF($B$3:$B$19,"Ocio",C3:C19) -> 0 | D23: =SUMIF($B$3:$B$19,"Ocio",D3:D19) -> 0 | E23: =SUMIF($B$3:$B$19,"Ocio",E3:E19) -> 0 | F23: =SUMIF($B$3:$B$19,"Ocio",F3:F19) -> 0 | G23: =SUMIF($B$3:$B$19,"Ocio",G3:G19) -> 0 | H23: =SUMIF($B$3:$B$19,"Ocio",H3:H19) -> 0 | I23: =SUMIF($B$3:$B$19,"Ocio",I3:I19) -> 241.66 | J23: =SUMIF($B$3:$B$19,"Ocio",J3:J19) -> 70.15 | ... N23: =SUMIF($B$3:$B$19,"Ocio",N3:N19) -> 0 | O23: =SUM(C23:N23) -> 568.65 | P23: =O23/$O$21 -> 0.61455744 | Q23: Total Ocio
A24: Total Ordinario | C24: =SUMIF($B$3:$B$19,"Ordinario",C3:C19) -> 0 | D24: =SUMIF($B$3:$B$19,"Ordinario",D3:D19) -> 0 | E24: =SUMIF($B$3:$B$19,"Ordinario",E3:E19) -> 0 | F24: =SUMIF($B$3:$B$19,"Ordinario",F3:F19) -> 0 | G24: =SUMIF($B$3:$B$19,"Ordinario",G3:G19) -> 0 | H24: =SUMIF($B$3:$B$19,"Ordinario",H3:H19) -> 0 | I24: =SUMIF($B$3:$B$19,"Ordinario",I3:I19) -> 15 | J24: =SUMIF($B$3:$B$19,"Ordinario",J3:J19) -> 0 | ... N24: =SUMIF($B$3:$B$19,"Ordinario",N3:N19) -> 0 | O24: =SUM(C24:N24) -> 43 | P24: =O24/$O$21 -> 0.046471415 | Q24: Total Ordinario
A25: Total Extraordinario Evitable | C25: =SUMIF($B$3:$B$19,"Extraordinario Evitable",C3:C19) -> 0 | D25: =SUMIF($B$3:$B$19,"Extraordinario Evitable",D3:D19) -> 0 | E25: =SUMIF($B$3:$B$19,"Extraordinario Evitable",E3:E19) -> 0 | F25: =SUMIF($B$3:$B$19,"Extraordinario Evitable",F3:F19) -> 0 | G25: =SUMIF($B$3:$B$19,"Extraordinario Evitable",G3:G19) -> 0 | H25: =SUMIF($B$3:$B$19,"Extraordinario Evitable",H3:H19) -> 0 | I25: =SUMIF($B$3:$B$19,"Extraordinario Evitable",I3:I19) -> 70 | J25: =SUMIF($B$3:$B$19,"Extraordinario Evitable",J3:J19) -> 6.35 | ... N25: =SUMIF($B$3:$B$19,"Extraordinario Evitable",N3:N19) -> 0 | O25: =SUM(C25:N25) -> 76.35 | P25: =O25/$O$21 -> 0.082513779 | Q25: Total Extraordinario Evitable
A26: Total Extraordinario Inevitable | C26: =SUMIF($B$3:$B$19,"Extraordinario Inevitable",C3:C19) -> 0 | D26: =SUMIF($B$3:$B$19,"Extraordinario Inevitable",D3:D19) -> 0 | E26: =SUMIF($B$3:$B$19,"Extraordinario Inevitable",E3:E19) -> 0 | F26: =SUMIF($B$3:$B$19,"Extraordinario Inevitable",F3:F19) -> 0 | G26: =SUMIF($B$3:$B$19,"Extraordinario Inevitable",G3:G19) -> 0 | H26: =SUMIF($B$3:$B$19,"Extraordinario Inevitable",H3:H19) -> 0 | I26: =SUMIF($B$3:$B$19,"Extraordinario Inevitable",I3:I19) -> 237.3 | J26: =SUMIF($B$3:$B$19,"Extraordinario Inevitable",J3:J19) -> 0 | ... N26: =SUMIF($B$3:$B$19,"Extraordinario Inevitable",N3:N19) -> 0 | O26: =SUM(C26:N26) -> 237.3 | P26: =O26/$O$21 -> 0.25645737 | Q26: Total Extraordinario Inevitable

Sheet Instrucciones
A1: Cómo usar este Excel de control de gastos
A3: 1. Cada mes tiene su propia pestaña (Enero...Diciembre). Ahí vas anotando cada gasto según ocurre.
A4: 2. Columnas de cada pestaña mensual:
A5: - Fecha: fecha del gasto
A6: - Descripción: texto libre (ej. 'Cena con amigos')
A7: - Categoría: elige de la lista desplegable (Videojuegos, Apuestas, Comida/Bebidas, etc.)
A8: - Tipo: se rellena SOLO, según la categoría elegida (Ocio u Ordinario)
A9: - Importe: cantidad en euros (número, sin símbolo €)
A10: 3. Las celdas en AZUL son las que tú rellenas. Las celdas en NEGRO tienen fórmulas — no las toques.
A11: 4. La pestaña 'Categorías' es la lista maestra: si quieres añadir o cambiar una categoría, edítala ahí
A12: (y el desplegable de los meses se actualizará solo).
A13: 5. La pestaña 'Visión General' se calcula sola a partir de los 12 meses: no hay que tocar nada ahí,
... A16: Ejemplo de una fila de gasto (así se vería en una pestaña de mes):
A17: Fecha | B17: Descripción | C17: Categoría | D17: Tipo | E17: Importe
A18: 15/07/2026 | B18: Cena con amigos | C18: Otros | D18: Ordinario | E18: 32.5

Sheet Categorías
A1: Categoría | B1: Tipo
A2: Videojuegos | B2: Ocio
A3: Apuestas | B3: Ocio
A4: Salidas/Ocio | B4: Ocio
A5: Suscripciones ocio | B5: Ocio
A6: Viajes | B6: Ocio
A7: Padel | B7: Ocio
A8: Alimentación | B8: Ocio
A9: Barça | B9: Ocio
A10: Vivienda/Alquiler | B10: Ordinario
A11: Transporte | B11: Ordinario
A12: Salud | B12: Ordinario
... A18: Otros extraordinarios | B18: Extraordinario Inevitable

Sheet Enero
A1: Gastos — Enero 2026
A2: Fecha | B2: Descripción | C2: Categoría | D2: Tipo | E2: Importe | G2: Resumen del mes
D3: =IFERROR(INDEX(Categorías!$B$2:$B$18,MATCH(C3,Categorías!$A$2:$A$18,0)),"") | G3: =Categorías!A2 -> Videojuegos | H3: =SUMIF($C$3:$C$32,G3,$E$3:$E$32) -> 0 | I3: =Categorías!B2 -> Ocio
D4: =IFERROR(INDEX(Categorías!$B$2:$B$18,MATCH(C4,Categorías!$A$2:$A$18,0)),"") | G4: =Categorías!A3 -> Apuestas | H4: =SUMIF($C$3:$C$32,G4,$E$3:$E$32) -> 0 | I4: =Categorías!B3 -> Ocio
D5: =IFERROR(INDEX(Categorías!$B$2:$B$18,MATCH(C5,Categorías!$A$2:$A$18,0)),"") | G5: =Categorías!A4 -> Salidas/Ocio | H5: =SUMIF($C$3:$C$32,G5,$E$3:$E$32) -> 0 | I5: =Categorías!B4 -> Ocio
D6: =IFERROR(INDEX(Categorías!$B$2:$B$18,MATCH(C6,Categorías!$A$2:$A$18,0)),"") | G6: =Categorías!A5 -> Suscripciones ocio | H6: =SUMIF($C$3:$C$32,G6,$E$3:$E$32) -> 0 | I6: =Categorías!B5 -> Ocio
D7: =IFERROR(INDEX(Categorías!$B$2:$B$18,MATCH(C7,Categorías!$A$2:$A$18,0)),"") | G7: =Categorías!A6 -> Viajes | H7: =SUMIF($C$3:$C$32,G7,$E$3:$E$32) -> 0 | I7: =Categorías!B6 -> Ocio
D8: =IFERROR(INDEX(Categorías!$B$2:$B$18,MATCH(C8,Categorías!$A$2:$A$18,0)),"") | G8: =Categorías!A7 -> Padel | H8: =SUMIF($C$3:$C$32,G8,$E$3:$E$32) -> 0 | I8: =Categorías!B7 -> Ocio
D9: =IFERROR(INDEX(Categorías!$B$2:$B$18,MATCH(C9,Categorías!$A$2:$A$18,0)),"") | G9: =Categorías!A8 -> Alimentación | H9: =SUMIF($C$3:$C$32,G9,$E$3:$E$32) -> 0 | I9: =Categorías!B8 -> Ocio
D10: =IFERROR(INDEX(Categorías!$B$2:$B$18,MATCH(C10,Categorías!$A$2:$A$18,0)),"") | G10: =Categorías!A9 -> Barça | H10: =SUMIF($C$3:$C$32,G10,$E$3:$E$32) -> 0 | I10: =Categorías!B9 -> Ocio
D11: =IFERROR(INDEX(Categorías!$B$2:$B$18,MATCH(C11,Categorías!$A$2:$A$18,0)),"") | G11: =Categorías!A10 -> Vivienda/Alquiler | H11: =SUMIF($C$3:$C$32,G11,$E$3:$E$32) -> 0 | I11: =Categorías!B10 -> Ordinario
D12: =IFERROR(INDEX(Categorías!$B$2:$B$18,MATCH(C12,Categorías!$A$2:$A$18,0)),"") | G12: =Categorías!A11 -> Transporte | H12: =SUMIF($C$3:$C$32,G12,$E$3:$E$32) -> 0 | I12: =Categorías!B11 -> Ordinario
D13: =IFERROR(INDEX(Categorías!$B$2:$B$18,MATCH(C13,Categorías!$A$2:$A$18,0)),"") | G13: =Categorías!A12 -> Salud | H13: =SUMIF($C$3:$C$32,G13,$E$3:$E$32) -> 0 | I13: =Categorías!B12 -> Ordinario
D14: =IFERROR(INDEX(Categorías!$B$2:$B$18,MATCH(C14,Categorías!$A$2:$A$18,0)),"") | G14: =Categorías!A13 -> Barbero | H14: =SUMIF($C$3:$C$32,G14,$E$3:$E$32) -> 0 | I14: =Categorías!B13 -> Ordinario
... D19: =IFERROR(INDEX(Categorías!$B$2:$B$18,MATCH(C19,Categorías!$A$2:$A$18,0)),"") | G19: =Categorías!A18 -> Otros extraordinarios | H19: =SUMIF($C$3:$C$32,G19,$E$3:$E$32) -> 0 | I19: =Categorías!B18 -> Extraordinario Inevitable
D20: =IFERROR(INDEX(Categorías!$B$2:$B$18,MATCH(C20,Categorías!$A$2:$A$18,0)),"")
D21: =IFERROR(INDEX(Categorías!$B$2:$B$18,MATCH(C21,Categorías!$A$2:$A$18,0)),"") | G21: Total Ocio | H21: =SUMIF($I$3:$I$19,"Ocio",$H$3:$H$19) -> 0
D22: =IFERROR(INDEX(Categorías!$B$2:$B$18,MATCH(C22,Categorías!$A$2:$A$18,0)),"") | G22: Total Ordinario | H22: =SUMIF($I$3:$I$19,"Ordinario",$H$3:$H$19) -> 0
D23: =IFERROR(INDEX(Categorías!$B$2:$B$18,MATCH(C23,Categorías!$A$2:$A$18,0)),"") | G23: Total Extraordinario | H23: =SUMIF($I$3:$I$19,"Extraordinario*",$H$3:$H$19) -> 0
D24: =IFERROR(INDEX(Categorías!$B$2:$B$18,MATCH(C24,Categorías!$A$2:$A$18,0)),"") | G24: Total Extraordinario Evitable | H24: =SUMIF($I$3:$I$19,"Extraordinario Evitable",$H$3:$H$19) -> 0
D25: =IFERROR(INDEX(Categorías!$B$2:$B$18,MATCH(C25,Categorías!$A$2:$A$18,0)),"") | G25: Total Extraordinario Inevitable | H25: =SUMIF($I$3:$I$19,"Extraordinario Inevitable",$H$3:$H$19) -> 0
D26: =IFERROR(INDEX(Categorías!$B$2:$B$18,MATCH(C26,Categorías!$A$2:$A$18,0)),"") | G26: TOTAL MES | H26: =SUM($E$3:$E$32) -> 0
D27: =IFERROR(INDEX(Categorías!$B$2:$B$18,MATCH(C27,Categorías!$A$2:$A$18,0)),"")
D28: =IFERROR(INDEX(Categorías!$B$2:$B$18,MATCH(C28,Categorías!$A$2:$A$18,0)),"")
D29: =IFERROR(INDEX(Categorías!$B$2:$B$18,MATCH(C29,Categorías!$A$2:$A$18,0)),"")
D30: =IFERROR(INDEX(Categorías!$B$2:$B$18,MATCH(C30,Categorías!$A$2:$A$18,0)),"")
D31: =IFERROR(INDEX(Categorías!$B$2:$B$18,MATCH(C31,Categorías!$A$2:$A$18,0)),"")
D32: =IFERROR(INDEX(Categorías!$B$2:$B$18,MATCH(C32,Categorías!$A$2:$A$18,0)),"")

Sheet Febrero
A1: Gastos — Febrero 2026
A2: Fecha | B2: Descripción | C2: Categoría | D2: Tipo | E2: Importe | G2: Resumen del mes
D3: =IFERROR(INDEX(Categorías!$B$2:$B$18,MATCH(C3,Categorías!$A$2:$A$18,0)),"") | G3: =Categorías!A2 -> Videojuegos | H3: =SUMIF($C$3:$C$32,G3,$E$3:$E$32) -> 0 | I3: =Categorías!B2 -> Ocio
D4: =IFERROR(INDEX(Categorías!$B$2:$B$18,MATCH(C4,Categorías!$A$2:$A$18,0)),"") | G4: =Categorías!A3 -> Apuestas | H4: =SUMIF($C$3:$C$32,G4,$E$3:$E$32) -> 0 | I4: =Categorías!B3 -> Ocio
D5: =IFERROR(INDEX(Categorías!$B$2:$B$18,MATCH(C5,Categorías!$A$2:$A$18,0)),"") | G5: =Categorías!A4 -> Salidas/Ocio | H5: =SUMIF($C$3:$C$32,G5,$E$3:$E$32) -> 0 | I5: =Categorías!B4 -> Ocio
D6: =IFERROR(INDEX(Categorías!$B$2:$B$18,MATCH(C6,Categorías!$A$2:$A$18,0)),"") | G6: =Categorías!A5 -> Suscripciones ocio | H6: =SUMIF($C$3:$C$32,G6,$E$3:$E$32) -> 0 | I6: =Categorías!B5 -> Ocio
D7: =IFERROR(INDEX(Categorías!$B$2:$B$18,MATCH(C7,Categorías!$A$2:$A$18,0)),"") | G7: =Categorías!A6 -> Viajes | H7: =SUMIF($C$3:$C$32,G7,$E$3:$E$32) -> 0 | I7: =Categorías!B6 -> Ocio
D8: =IFERROR(INDEX(Categorías!$B$2:$B$18,MATCH(C8,Categorías!$A$2:$A$18,0)),"") | G8: =Categorías!A7 -> Padel | H8: =SUMIF($C$3:$C$32,G8,$E$3:$E$32) -> 0 | I8: =Categorías!B7 -> Ocio
D9: =IFERROR(INDEX(Categorías!$B$2:$B$18,MATCH(C9,Categorías!$A$2:$A$18,0)),"") | G9: =Categorías!A8 -> Alimentación | H9: =SUMIF($C$3:$C$32,G9,$E$3:$E$32) -> 0 | I9: =Categorías!B8 -> Ocio
D10: =IFERROR(INDEX(Categorías!$B$2:$B$18,MATCH(C10,Categorías!$A$2:$A$18,0)),"") | G10: =Categorías!A9 -> Barça | H10: =SUMIF($C$3:$C$32,G10,$E$3:$E$32) -> 0 | I10: =Categorías!B9 -> Ocio
D11: =IFERROR(INDEX(Categorías!$B$2:$B$18,MATCH(C11,Categorías!$A$2:$A$18,0)),"") | G11: =Categorías!A10 -> Vivienda/Alquiler | H11: =SUMIF($C$3:$C$32,G11,$E$3:$E$32) -> 0 | I11: =Categorías!B10 -> Ordinario
D12: =IFERROR(INDEX(Categorías!$B$2:$B$18,MATCH(C12,Categorías!$A$2:$A$18,0)),"") | G12: =Categorías!A11 -> Transporte | H12: =SUMIF($C$3:$C$32,G12,$E$3:$E$32) -> 0 | I12: =Categorías!B11 -> Ordinario
D13: =IFERROR(INDEX(Categorías!$B$2:$B$18,MATCH(C13,Categorías!$A$2:$A$18,0)),"") | G13: =Categorías!A12 -> Salud | H13: =SUMIF($C$3:$C$32,G13,$E$3:$E$32) -> 0 | I13: =Categorías!B12 -> Ordinario
D14: =IFERROR(INDEX(Categorías!$B$2:$B$18,MATCH(C14,Categorías!$A$2:$A$18,0)),"") | G14: =Categorías!A13 -> Barbero | H14: =SUMIF($C$3:$C$32,G14,$E$3:$E$32) -> 0 | I14: =Categorías!B13 -> Ordinario
... D19: =IFERROR(INDEX(Categorías!$B$2:$B$18,MATCH(C19,Categorías!$A$2:$A$18,0)),"") | G19: =Categorías!A18 -> Otros extraordinarios | H19: =SUMIF($C$3:$C$32,G19,$E$3:$E$32) -> 0 | I19: =Categorías!B18 -> Extraordinario Inevitable
D20: =IFERROR(INDEX(Categorías!$B$2:$B$18,MATCH(C20,Categorías!$A$2:$A$18,0)),"")
D21: =IFERROR(INDEX(Categorías!$B$2:$B$18,MATCH(C21,Categorías!$A$2:$A$18,0)),"") | G21: Total Ocio | H21: =SUMIF($I$3:$I$19,"Ocio",$H$3:$H$19) -> 0
D22: =IFERROR(INDEX(Categorías!$B$2:$B$18,MATCH(C22,Categorías!$A$2:$A$18,0)),"") | G22: Total Ordinario | H22: =SUMIF($I$3:$I$19,"Ordinario",$H$3:$H$19) -> 0
D23: =IFERROR(INDEX(Categorías!$B$2:$B$18,MATCH(C23,Categorías!$A$2:$A$18,0)),"") | G23: Total Extraordinario | H23: =SUMIF($I$3:$I$19,"Extraordinario*",$H$3:$H$19) -> 0
D24: =IFERROR(INDEX(Categorías!$B$2:$B$18,MATCH(C24,Categorías!$A$2:$A$18,0)),"") | G24: Total Extraordinario Evitable | H24: =SUMIF($I$3:$I$19,"Extraordinario Evitable",$H$3:$H$19) -> 0
D25: =IFERROR(INDEX(Categorías!$B$2:$B$18,MATCH(C25,Categorías!$A$2:$A$18,0)),"") | G25: Total Extraordinario Inevitable | H25: =SUMIF($I$3:$I$19,"Extraordinario Inevitable",$H$3:$H$19) -> 0
D26: =IFERROR(INDEX(Categorías!$B$2:$B$18,MATCH(C26,Categorías!$A$2:$A$18,0)),"") | G26: TOTAL MES | H26: =SUM($E$3:$E$32) -> 0
D27: =IFERROR(INDEX(Categorías!$B$2:$B$18,MATCH(C27,Categorías!$A$2:$A$18,0)),"")
D28: =IFERROR(INDEX(Categorías!$B$2:$B$18,MATCH(C28,Categorías!$A$2:$A$18,0)),"")
D29: =IFERROR(INDEX(Categorías!$B$2:$B$18,MATCH(C29,Categorías!$A$2:$A$18,0)),"")
D30: =IFERROR(INDEX(Categorías!$B$2:$B$18,MATCH(C30,Categorías!$A$2:$A$18,0)),"")
D31: =IFERROR(INDEX(Categorías!$B$2:$B$18,MATCH(C31,Categorías!$A$2:$A$18,0)),"")
D32: =IFERROR(INDEX(Categorías!$B$2:$B$18,MATCH(C32,Categorías!$A$2:$A$18,0)),"")

Sheet Marzo
A1: Gastos — Marzo 2026
A2: Fecha | B2: Descripción | C2: Categoría | D2: Tipo | E2: Importe | G2: Resumen del mes
D3: =IFERROR(INDEX(Categorías!$B$2:$B$18,MATCH(C3,Categorías!$A$2:$A$18,0)),"") | G3: =Categorías!A2 -> Videojuegos | H3: =SUMIF($C$3:$C$32,G3,$E$3:$E$32) -> 0 | I3: =Categorías!B2 -> Ocio
D4: =IFERROR(INDEX(Categorías!$B$2:$B$18,MATCH(C4,Categorías!$A$2:$A$18,0)),"") | G4: =Categorías!A3 -> Apuestas | H4: =SUMIF($C$3:$C$32,G4,$E$3:$E$32) -> 0 | I4: =Categorías!B3 -> Ocio
D5: =IFERROR(INDEX(Categorías!$B$2:$B$18,MATCH(C5,Categorías!$A$2:$A$18,0)),"") | G5: =Categorías!A4 -> Salidas/Ocio | H5: =SUMIF($C$3:$C$32,G5,$E$3:$E$32) -> 0 | I5: =Categorías!B4 -> Ocio
D6: =IFERROR(INDEX(Categorías!$B$2:$B$18,MATCH(C6,Categorías!$A$2:$A$18,0)),"") | G6: =Categorías!A5 -> Suscripciones ocio | H6: =SUMIF($C$3:$C$32,G6,$E$3:$E$32) -> 0 | I6: =Categorías!B5 -> Ocio
D7: =IFERROR(INDEX(Categorías!$B$2:$B$18,MATCH(C7,Categorías!$A$2:$A$18,0)),"") | G7: =Categorías!A6 -> Viajes | H7: =SUMIF($C$3:$C$32,G7,$E$3:$E$32) -> 0 | I7: =Categorías!B6 -> Ocio
D8: =IFERROR(INDEX(Categorías!$B$2:$B$18,MATCH(C8,Categorías!$A$2:$A$18,0)),"") | G8: =Categorías!A7 -> Padel | H8: =SUMIF($C$3:$C$32,G8,$E$3:$E$32) -> 0 | I8: =Categorías!B7 -> Ocio
D9: =IFERROR(INDEX(Categorías!$B$2:$B$18,MATCH(C9,Categorías!$A$2:$A$18,0)),"") | G9: =Categorías!A8 -> Alimentación | H9: =SUMIF($C$3:$C$32,G9,$E$3:$E$32) -> 0 | I9: =Categorías!B8 -> Ocio
D10: =IFERROR(INDEX(Categorías!$B$2:$B$18,MATCH(C10,Categorías!$A$2:$A$18,0)),"") | G10: =Categorías!A9 -> Barça | H10: =SUMIF($C$3:$C$32,G10,$E$3:$E$32) -> 0 | I10: =Categorías!B9 -> Ocio
D11: =IFERROR(INDEX(Categorías!$B$2:$B$18,MATCH(C11,Categorías!$A$2:$A$18,0)),"") | G11: =Categorías!A10 -> Vivienda/Alquiler | H11: =SUMIF($C$3:$C$32,G11,$E$3:$E$32) -> 0 | I11: =Categorías!B10 -> Ordinario
D12: =IFERROR(INDEX(Categorías!$B$2:$B$18,MATCH(C12,Categorías!$A$2:$A$18,0)),"") | G12: =Categorías!A11 -> Transporte | H12: =SUMIF($C$3:$C$32,G12,$E$3:$E$32) -> 0 | I12: =Categorías!B11 -> Ordinario
D13: =IFERROR(INDEX(Categorías!$B$2:$B$18,MATCH(C13,Categorías!$A$2:$A$18,0)),"") | G13: =Categorías!A12 -> Salud | H13: =SUMIF($C$3:$C$32,G13,$E$3:$E$32) -> 0 | I13: =Categorías!B12 -> Ordinario
D14: =IFERROR(INDEX(Categorías!$B$2:$B$18,MATCH(C14,Categorías!$A$2:$A$18,0)),"") | G14: =Categorías!A13 -> Barbero | H14: =SUMIF($C$3:$C$32,G14,$E$3:$E$32) -> 0 | I14: =Categorías!B13 -> Ordinario
... D19: =IFERROR(INDEX(Categorías!$B$2:$B$18,MATCH(C19,Categorías!$A$2:$A$18,0)),"") | G19: =Categorías!A18 -> Otros extraordinarios | H19: =SUMIF($C$3:$C$32,G19,$E$3:$E$32) -> 0 | I19: =Categorías!B18 -> Extraordinario Inevitable
D20: =IFERROR(INDEX(Categorías!$B$2:$B$18,MATCH(C20,Categorías!$A$2:$A$18,0)),"")
D21: =IFERROR(INDEX(Categorías!$B$2:$B$18,MATCH(C21,Categorías!$A$2:$A$18,0)),"") | G21: Total Ocio | H21: =SUMIF($I$3:$I$19,"Ocio",$H$3:$H$19) -> 0
D22: =IFERROR(INDEX(Categorías!$B$2:$B$18,MATCH(C22,Categorías!$A$2:$A$18,0)),"") | G22: Total Ordinario | H22: =SUMIF($I$3:$I$19,"Ordinario",$H$3:$H$19) -> 0
D23: =IFERROR(INDEX(Categorías!$B$2:$B$18,MATCH(C23,Categorías!$A$2:$A$18,0)),"") | G23: Total Extraordinario | H23: =SUMIF($I$3:$I$19,"Extraordinario*",$H$3:$H$19) -> 0
D24: =IFERROR(INDEX(Categorías!$B$2:$B$18,MATCH(C24,Categorías!$A$2:$A$18,0)),"") | G24: Total Extraordinario Evitable | H24: =SUMIF($I$3:$I$19,"Extraordinario Evitable",$H$3:$H$19) -> 0
D25: =IFERROR(INDEX(Categorías!$B$2:$B$18,MATCH(C25,Categorías!$A$2:$A$18,0)),"") | G25: Total Extraordinario Inevitable | H25: =SUMIF($I$3:$I$19,"Extraordinario Inevitable",$H$3:$H$19) -> 0
D26: =IFERROR(INDEX(Categorías!$B$2:$B$18,MATCH(C26,Categorías!$A$2:$A$18,0)),"") | G26: TOTAL MES | H26: =SUM($E$3:$E$32) -> 0
D27: =IFERROR(INDEX(Categorías!$B$2:$B$18,MATCH(C27,Categorías!$A$2:$A$18,0)),"")
D28: =IFERROR(INDEX(Categorías!$B$2:$B$18,MATCH(C28,Categorías!$A$2:$A$18,0)),"")
D29: =IFERROR(INDEX(Categorías!$B$2:$B$18,MATCH(C29,Categorías!$A$2:$A$18,0)),"")
D30: =IFERROR(INDEX(Categorías!$B$2:$B$18,MATCH(C30,Categorías!$A$2:$A$18,0)),"")
D31: =IFERROR(INDEX(Categorías!$B$2:$B$18,MATCH(C31,Categorías!$A$2:$A$18,0)),"")
D32: =IFERROR(INDEX(Categorías!$B$2:$B$18,MATCH(C32,Categorías!$A$2:$A$18,0)),"")

Sheet Abril
A1: Gastos — Abril 2026
A2: Fecha | B2: Descripción | C2: Categoría | D2: Tipo | E2: Importe | G2: Resumen del mes
D3: =IFERROR(INDEX(Categorías!$B$2:$B$18,MATCH(C3,Categorías!$A$2:$A$18,0)),"") | G3: =Categorías!A2 -> Videojuegos | H3: =SUMIF($C$3:$C$32,G3,$E$3:$E$32) -> 0 | I3: =Categorías!B2 -> Ocio
D4: =IFERROR(INDEX(Categorías!$B$2:$B$18,MATCH(C4,Categorías!$A$2:$A$18,0)),"") | G4: =Categorías!A3 -> Apuestas | H4: =SUMIF($C$3:$C$32,G4,$E$3:$E$32) -> 0 | I4: =Categorías!B3 -> Ocio
D5: =IFERROR(INDEX(Categorías!$B$2:$B$18,MATCH(C5,Categorías!$A$2:$A$18,0)),"") | G5: =Categorías!A4 -> Salidas/Ocio | H5: =SUMIF($C$3:$C$32,G5,$E$3:$E$32) -> 0 | I5: =Categorías!B4 -> Ocio
D6: =IFERROR(INDEX(Categorías!$B$2:$B$18,MATCH(C6,Categorías!$A$2:$A$18,0)),"") | G6: =Categorías!A5 -> Suscripciones ocio | H6: =SUMIF($C$3:$C$32,G6,$E$3:$E$32) -> 0 | I6: =Categorías!B5 -> Ocio
D7: =IFERROR(INDEX(Categorías!$B$2:$B$18,MATCH(C7,Categorías!$A$2:$A$18,0)),"") | G7: =Categorías!A6 -> Viajes | H7: =SUMIF($C$3:$C$32,G7,$E$3:$E$32) -> 0 | I7: =Categorías!B6 -> Ocio
D8: =IFERROR(INDEX(Categorías!$B$2:$B$18,MATCH(C8,Categorías!$A$2:$A$18,0)),"") | G8: =Categorías!A7 -> Padel | H8: =SUMIF($C$3:$C$32,G8,$E$3:$E$32) -> 0 | I8: =Categorías!B7 -> Ocio
D9: =IFERROR(INDEX(Categorías!$B$2:$B$18,MATCH(C9,Categorías!$A$2:$A$18,0)),"") | G9: =Categorías!A8 -> Alimentación | H9: =SUMIF($C$3:$C$32,G9,$E$3:$E$32) -> 0 | I9: =Categorías!B8 -> Ocio
D10: =IFERROR(INDEX(Categorías!$B$2:$B$18,MATCH(C10,Categorías!$A$2:$A$18,0)),"") | G10: =Categorías!A9 -> Barça | H10: =SUMIF($C$3:$C$32,G10,$E$3:$E$32) -> 0 | I10: =Categorías!B9 -> Ocio
D11: =IFERROR(INDEX(Categorías!$B$2:$B$18,MATCH(C11,Categorías!$A$2:$A$18,0)),"") | G11: =Categorías!A10 -> Vivienda/Alquiler | H11: =SUMIF($C$3:$C$32,G11,$E$3:$E$32) -> 0 | I11: =Categorías!B10 -> Ordinario
D12: =IFERROR(INDEX(Categorías!$B$2:$B$18,MATCH(C12,Categorías!$A$2:$A$18,0)),"") | G12: =Categorías!A11 -> Transporte | H12: =SUMIF($C$3:$C$32,G12,$E$3:$E$32) -> 0 | I12: =Categorías!B11 -> Ordinario
D13: =IFERROR(INDEX(Categorías!$B$2:$B$18,MATCH(C13,Categorías!$A$2:$A$18,0)),"") | G13: =Categorías!A12 -> Salud | H13: =SUMIF($C$3:$C$32,G13,$E$3:$E$32) -> 0 | I13: =Categorías!B12 -> Ordinario
D14: =IFERROR(INDEX(Categorías!$B$2:$B$18,MATCH(C14,Categorías!$A$2:$A$18,0)),"") | G14: =Categorías!A13 -> Barbero | H14: =SUMIF($C$3:$C$32,G14,$E$3:$E$32) -> 0 | I14: =Categorías!B13 -> Ordinario
... D19: =IFERROR(INDEX(Categorías!$B$2:$B$18,MATCH(C19,Categorías!$A$2:$A$18,0)),"") | G19: =Categorías!A18 -> Otros extraordinarios | H19: =SUMIF($C$3:$C$32,G19,$E$3:$E$32) -> 0 | I19: =Categorías!B18 -> Extraordinario Inevitable
D20: =IFERROR(INDEX(Categorías!$B$2:$B$18,MATCH(C20,Categorías!$A$2:$A$18,0)),"")
D21: =IFERROR(INDEX(Categorías!$B$2:$B$18,MATCH(C21,Categorías!$A$2:$A$18,0)),"") | G21: Total Ocio | H21: =SUMIF($I$3:$I$19,"Ocio",$H$3:$H$19) -> 0
D22: =IFERROR(INDEX(Categorías!$B$2:$B$18,MATCH(C22,Categorías!$A$2:$A$18,0)),"") | G22: Total Ordinario | H22: =SUMIF($I$3:$I$19,"Ordinario",$H$3:$H$19) -> 0
D23: =IFERROR(INDEX(Categorías!$B$2:$B$18,MATCH(C23,Categorías!$A$2:$A$18,0)),"") | G23: Total Extraordinario | H23: =SUMIF($I$3:$I$19,"Extraordinario*",$H$3:$H$19) -> 0
D24: =IFERROR(INDEX(Categorías!$B$2:$B$18,MATCH(C24,Categorías!$A$2:$A$18,0)),"") | G24: Total Extraordinario Evitable | H24: =SUMIF($I$3:$I$19,"Extraordinario Evitable",$H$3:$H$19) -> 0
D25: =IFERROR(INDEX(Categorías!$B$2:$B$18,MATCH(C25,Categorías!$A$2:$A$18,0)),"") | G25: Total Extraordinario Inevitable | H25: =SUMIF($I$3:$I$19,"Extraordinario Inevitable",$H$3:$H$19) -> 0
D26: =IFERROR(INDEX(Categorías!$B$2:$B$18,MATCH(C26,Categorías!$A$2:$A$18,0)),"") | G26: TOTAL MES | H26: =SUM($E$3:$E$32) -> 0
D27: =IFERROR(INDEX(Categorías!$B$2:$B$18,MATCH(C27,Categorías!$A$2:$A$18,0)),"")
D28: =IFERROR(INDEX(Categorías!$B$2:$B$18,MATCH(C28,Categorías!$A$2:$A$18,0)),"")
D29: =IFERROR(INDEX(Categorías!$B$2:$B$18,MATCH(C29,Categorías!$A$2:$A$18,0)),"")
D30: =IFERROR(INDEX(Categorías!$B$2:$B$18,MATCH(C30,Categorías!$A$2:$A$18,0)),"")
D31: =IFERROR(INDEX(Categorías!$B$2:$B$18,MATCH(C31,Categorías!$A$2:$A$18,0)),"")
D32: =IFERROR(INDEX(Categorías!$B$2:$B$18,MATCH(C32,Categorías!$A$2:$A$18,0)),"")

Sheet Mayo
A1: Gastos — Mayo 2026
A2: Fecha | B2: Descripción | C2: Categoría | D2: Tipo | E2: Importe | G2: Resumen del mes
D3: =IFERROR(INDEX(Categorías!$B$2:$B$18,MATCH(C3,Categorías!$A$2:$A$18,0)),"") | G3: =Categorías!A2 -> Videojuegos | H3: =SUMIF($C$3:$C$32,G3,$E$3:$E$32) -> 0 | I3: =Categorías!B2 -> Ocio
D4: =IFERROR(INDEX(Categorías!$B$2:$B$18,MATCH(C4,Categorías!$A$2:$A$18,0)),"") | G4: =Categorías!A3 -> Apuestas | H4: =SUMIF($C$3:$C$32,G4,$E$3:$E$32) -> 0 | I4: =Categorías!B3 -> Ocio
D5: =IFERROR(INDEX(Categorías!$B$2:$B$18,MATCH(C5,Categorías!$A$2:$A$18,0)),"") | G5: =Categorías!A4 -> Salidas/Ocio | H5: =SUMIF($C$3:$C$32,G5,$E$3:$E$32) -> 0 | I5: =Categorías!B4 -> Ocio
D6: =IFERROR(INDEX(Categorías!$B$2:$B$18,MATCH(C6,Categorías!$A$2:$A$18,0)),"") | G6: =Categorías!A5 -> Suscripciones ocio | H6: =SUMIF($C$3:$C$32,G6,$E$3:$E$32) -> 0 | I6: =Categorías!B5 -> Ocio
D7: =IFERROR(INDEX(Categorías!$B$2:$B$18,MATCH(C7,Categorías!$A$2:$A$18,0)),"") | G7: =Categorías!A6 -> Viajes | H7: =SUMIF($C$3:$C$32,G7,$E$3:$E$32) -> 0 | I7: =Categorías!B6 -> Ocio
D8: =IFERROR(INDEX(Categorías!$B$2:$B$18,MATCH(C8,Categorías!$A$2:$A$18,0)),"") | G8: =Categorías!A7 -> Padel | H8: =SUMIF($C$3:$C$32,G8,$E$3:$E$32) -> 0 | I8: =Categorías!B7 -> Ocio
D9: =IFERROR(INDEX(Categorías!$B$2:$B$18,MATCH(C9,Categorías!$A$2:$A$18,0)),"") | G9: =Categorías!A8 -> Alimentación | H9: =SUMIF($C$3:$C$32,G9,$E$3:$E$32) -> 0 | I9: =Categorías!B8 -> Ocio
D10: =IFERROR(INDEX(Categorías!$B$2:$B$18,MATCH(C10,Categorías!$A$2:$A$18,0)),"") | G10: =Categorías!A9 -> Barça | H10: =SUMIF($C$3:$C$32,G10,$E$3:$E$32) -> 0 | I10: =Categorías!B9 -> Ocio
D11: =IFERROR(INDEX(Categorías!$B$2:$B$18,MATCH(C11,Categorías!$A$2:$A$18,0)),"") | G11: =Categorías!A10 -> Vivienda/Alquiler | H11: =SUMIF($C$3:$C$32,G11,$E$3:$E$32) -> 0 | I11: =Categorías!B10 -> Ordinario
D12: =IFERROR(INDEX(Categorías!$B$2:$B$18,MATCH(C12,Categorías!$A$2:$A$18,0)),"") | G12: =Categorías!A11 -> Transporte | H12: =SUMIF($C$3:$C$32,G12,$E$3:$E$32) -> 0 | I12: =Categorías!B11 -> Ordinario
D13: =IFERROR(INDEX(Categorías!$B$2:$B$18,MATCH(C13,Categorías!$A$2:$A$18,0)),"") | G13: =Categorías!A12 -> Salud | H13: =SUMIF($C$3:$C$32,G13,$E$3:$E$32) -> 0 | I13: =Categorías!B12 -> Ordinario
D14: =IFERROR(INDEX(Categorías!$B$2:$B$18,MATCH(C14,Categorías!$A$2:$A$18,0)),"") | G14: =Categorías!A13 -> Barbero | H14: =SUMIF($C$3:$C$32,G14,$E$3:$E$32) -> 0 | I14: =Categorías!B13 -> Ordinario
... D19: =IFERROR(INDEX(Categorías!$B$2:$B$18,MATCH(C19,Categorías!$A$2:$A$18,0)),"") | G19: =Categorías!A18 -> Otros extraordinarios | H19: =SUMIF($C$3:$C$32,G19,$E$3:$E$32) -> 0 | I19: =Categorías!B18 -> Extraordinario Inevitable
D20: =IFERROR(INDEX(Categorías!$B$2:$B$18,MATCH(C20,Categorías!$A$2:$A$18,0)),"")
D21: =IFERROR(INDEX(Categorías!$B$2:$B$18,MATCH(C21,Categorías!$A$2:$A$18,0)),"") | G21: Total Ocio | H21: =SUMIF($I$3:$I$19,"Ocio",$H$3:$H$19) -> 0
D22: =IFERROR(INDEX(Categorías!$B$2:$B$18,MATCH(C22,Categorías!$A$2:$A$18,0)),"") | G22: Total Ordinario | H22: =SUMIF($I$3:$I$19,"Ordinario",$H$3:$H$19) -> 0
D23: =IFERROR(INDEX(Categorías!$B$2:$B$18,MATCH(C23,Categorías!$A$2:$A$18,0)),"") | G23: Total Extraordinario | H23: =SUMIF($I$3:$I$19,"Extraordinario*",$H$3:$H$19) -> 0
D24: =IFERROR(INDEX(Categorías!$B$2:$B$18,MATCH(C24,Categorías!$A$2:$A$18,0)),"") | G24: Total Extraordinario Evitable | H24: =SUMIF($I$3:$I$19,"Extraordinario Evitable",$H$3:$H$19) -> 0
D25: =IFERROR(INDEX(Categorías!$B$2:$B$18,MATCH(C25,Categorías!$A$2:$A$18,0)),"") | G25: Total Extraordinario Inevitable | H25: =SUMIF($I$3:$I$19,"Extraordinario Inevitable",$H$3:$H$19) -> 0
D26: =IFERROR(INDEX(Categorías!$B$2:$B$18,MATCH(C26,Categorías!$A$2:$A$18,0)),"") | G26: TOTAL MES | H26: =SUM($E$3:$E$32) -> 0
D27: =IFERROR(INDEX(Categorías!$B$2:$B$18,MATCH(C27,Categorías!$A$2:$A$18,0)),"")
D28: =IFERROR(INDEX(Categorías!$B$2:$B$18,MATCH(C28,Categorías!$A$2:$A$18,0)),"")
D29: =IFERROR(INDEX(Categorías!$B$2:$B$18,MATCH(C29,Categorías!$A$2:$A$18,0)),"")
D30: =IFERROR(INDEX(Categorías!$B$2:$B$18,MATCH(C30,Categorías!$A$2:$A$18,0)),"")
D31: =IFERROR(INDEX(Categorías!$B$2:$B$18,MATCH(C31,Categorías!$A$2:$A$18,0)),"")
D32: =IFERROR(INDEX(Categorías!$B$2:$B$18,MATCH(C32,Categorías!$A$2:$A$18,0)),"")

Sheet Junio
A1: Gastos — Junio 2026
A2: Fecha | B2: Descripción | C2: Categoría | D2: Tipo | E2: Importe | G2: Resumen del mes
D3: =IFERROR(INDEX(Categorías!$B$2:$B$18,MATCH(C3,Categorías!$A$2:$A$18,0)),"") | G3: =Categorías!A2 -> Videojuegos | H3: =SUMIF($C$3:$C$32,G3,$E$3:$E$32) -> 0 | I3: =Categorías!B2 -> Ocio
D4: =IFERROR(INDEX(Categorías!$B$2:$B$18,MATCH(C4,Categorías!$A$2:$A$18,0)),"") | G4: =Categorías!A3 -> Apuestas | H4: =SUMIF($C$3:$C$32,G4,$E$3:$E$32) -> 0 | I4: =Categorías!B3 -> Ocio
D5: =IFERROR(INDEX(Categorías!$B$2:$B$18,MATCH(C5,Categorías!$A$2:$A$18,0)),"") | G5: =Categorías!A4 -> Salidas/Ocio | H5: =SUMIF($C$3:$C$32,G5,$E$3:$E$32) -> 0 | I5: =Categorías!B4 -> Ocio
D6: =IFERROR(INDEX(Categorías!$B$2:$B$18,MATCH(C6,Categorías!$A$2:$A$18,0)),"") | G6: =Categorías!A5 -> Suscripciones ocio | H6: =SUMIF($C$3:$C$32,G6,$E$3:$E$32) -> 0 | I6: =Categorías!B5 -> Ocio
D7: =IFERROR(INDEX(Categorías!$B$2:$B$18,MATCH(C7,Categorías!$A$2:$A$18,0)),"") | G7: =Categorías!A6 -> Viajes | H7: =SUMIF($C$3:$C$32,G7,$E$3:$E$32) -> 0 | I7: =Categorías!B6 -> Ocio
D8: =IFERROR(INDEX(Categorías!$B$2:$B$18,MATCH(C8,Categorías!$A$2:$A$18,0)),"") | G8: =Categorías!A7 -> Padel | H8: =SUMIF($C$3:$C$32,G8,$E$3:$E$32) -> 0 | I8: =Categorías!B7 -> Ocio
D9: =IFERROR(INDEX(Categorías!$B$2:$B$18,MATCH(C9,Categorías!$A$2:$A$18,0)),"") | G9: =Categorías!A8 -> Alimentación | H9: =SUMIF($C$3:$C$32,G9,$E$3:$E$32) -> 0 | I9: =Categorías!B8 -> Ocio
D10: =IFERROR(INDEX(Categorías!$B$2:$B$18,MATCH(C10,Categorías!$A$2:$A$18,0)),"") | G10: =Categorías!A9 -> Barça | H10: =SUMIF($C$3:$C$32,G10,$E$3:$E$32) -> 0 | I10: =Categorías!B9 -> Ocio
D11: =IFERROR(INDEX(Categorías!$B$2:$B$18,MATCH(C11,Categorías!$A$2:$A$18,0)),"") | G11: =Categorías!A10 -> Vivienda/Alquiler | H11: =SUMIF($C$3:$C$32,G11,$E$3:$E$32) -> 0 | I11: =Categorías!B10 -> Ordinario
D12: =IFERROR(INDEX(Categorías!$B$2:$B$18,MATCH(C12,Categorías!$A$2:$A$18,0)),"") | G12: =Categorías!A11 -> Transporte | H12: =SUMIF($C$3:$C$32,G12,$E$3:$E$32) -> 0 | I12: =Categorías!B11 -> Ordinario
D13: =IFERROR(INDEX(Categorías!$B$2:$B$18,MATCH(C13,Categorías!$A$2:$A$18,0)),"") | G13: =Categorías!A12 -> Salud | H13: =SUMIF($C$3:$C$32,G13,$E$3:$E$32) -> 0 | I13: =Categorías!B12 -> Ordinario
D14: =IFERROR(INDEX(Categorías!$B$2:$B$18,MATCH(C14,Categorías!$A$2:$A$18,0)),"") | G14: =Categorías!A13 -> Barbero | H14: =SUMIF($C$3:$C$32,G14,$E$3:$E$32) -> 0 | I14: =Categorías!B13 -> Ordinario
... D19: =IFERROR(INDEX(Categorías!$B$2:$B$18,MATCH(C19,Categorías!$A$2:$A$18,0)),"") | G19: =Categorías!A18 -> Otros extraordinarios | H19: =SUMIF($C$3:$C$32,G19,$E$3:$E$32) -> 0 | I19: =Categorías!B18 -> Extraordinario Inevitable
D20: =IFERROR(INDEX(Categorías!$B$2:$B$18,MATCH(C20,Categorías!$A$2:$A$18,0)),"")
D21: =IFERROR(INDEX(Categorías!$B$2:$B$18,MATCH(C21,Categorías!$A$2:$A$18,0)),"") | G21: Total Ocio | H21: =SUMIF($I$3:$I$19,"Ocio",$H$3:$H$19) -> 0
D22: =IFERROR(INDEX(Categorías!$B$2:$B$18,MATCH(C22,Categorías!$A$2:$A$18,0)),"") | G22: Total Ordinario | H22: =SUMIF($I$3:$I$19,"Ordinario",$H$3:$H$19) -> 0
D23: =IFERROR(INDEX(Categorías!$B$2:$B$18,MATCH(C23,Categorías!$A$2:$A$18,0)),"") | G23: Total Extraordinario | H23: =SUMIF($I$3:$I$19,"Extraordinario*",$H$3:$H$19) -> 0
D24: =IFERROR(INDEX(Categorías!$B$2:$B$18,MATCH(C24,Categorías!$A$2:$A$18,0)),"") | G24: Total Extraordinario Evitable | H24: =SUMIF($I$3:$I$19,"Extraordinario Evitable",$H$3:$H$19) -> 0
D25: =IFERROR(INDEX(Categorías!$B$2:$B$18,MATCH(C25,Categorías!$A$2:$A$18,0)),"") | G25: Total Extraordinario Inevitable | H25: =SUMIF($I$3:$I$19,"Extraordinario Inevitable",$H$3:$H$19) -> 0
D26: =IFERROR(INDEX(Categorías!$B$2:$B$18,MATCH(C26,Categorías!$A$2:$A$18,0)),"") | G26: TOTAL MES | H26: =SUM($E$3:$E$32) -> 0
D27: =IFERROR(INDEX(Categorías!$B$2:$B$18,MATCH(C27,Categorías!$A$2:$A$18,0)),"")
D28: =IFERROR(INDEX(Categorías!$B$2:$B$18,MATCH(C28,Categorías!$A$2:$A$18,0)),"")
D29: =IFERROR(INDEX(Categorías!$B$2:$B$18,MATCH(C29,Categorías!$A$2:$A$18,0)),"")
D30: =IFERROR(INDEX(Categorías!$B$2:$B$18,MATCH(C30,Categorías!$A$2:$A$18,0)),"")
D31: =IFERROR(INDEX(Categorías!$B$2:$B$18,MATCH(C31,Categorías!$A$2:$A$18,0)),"")
D32: =IFERROR(INDEX(Categorías!$B$2:$B$18,MATCH(C32,Categorías!$A$2:$A$18,0)),"")

Sheet Julio
A1: Gastos — Julio 2026
A2: Fecha | B2: Descripción | C2: Categoría | D2: Tipo | E2: Importe | G2: Resumen del mes
A3: 46204 | B3: Paki | C3: Alimentación | D3: =IFERROR(INDEX(Categorías!$B$2:$B$18,MATCH(C3,Categorías!$A$2:$A$18,0)),"") -> Ocio | E3: 3 | G3: =Categorías!A2 -> Videojuegos | H3: =SUMIF($C$3:$C$32,G3,$E$3:$E$32) -> 40 | I3: =Categorías!B2 -> Ocio
A4: 46206 | B4: Flores | C4: Regalos | D4: =IFERROR(INDEX(Categorías!$B$2:$B$18,MATCH(C4,Categorías!$A$2:$A$18,0)),"") -> Extraordinario Evitable | E4: 20 | G4: =Categorías!A3 -> Apuestas | H4: =SUMIF($C$3:$C$32,G4,$E$3:$E$32) -> 40 | I4: =Categorías!B3 -> Ocio
A5: 46209 | B5: Monster | C5: Alimentación | D5: =IFERROR(INDEX(Categorías!$B$2:$B$18,MATCH(C5,Categorías!$A$2:$A$18,0)),"") -> Ocio | E5: 1.8 | G5: =Categorías!A4 -> Salidas/Ocio | H5: =SUMIF($C$3:$C$32,G5,$E$3:$E$32) -> 122.4 | I5: =Categorías!B4 -> Ocio
A6: 46210 | B6: Padel | C6: Padel | D6: =IFERROR(INDEX(Categorías!$B$2:$B$18,MATCH(C6,Categorías!$A$2:$A$18,0)),"") -> Ocio | E6: =21.84/4 -> 5.46 | G6: =Categorías!A5 -> Suscripciones ocio | H6: =SUMIF($C$3:$C$32,G6,$E$3:$E$32) -> 8.5 | I6: =Categorías!B5 -> Ocio
A7: 46210 | B7: Padel | C7: Padel | D7: =IFERROR(INDEX(Categorías!$B$2:$B$18,MATCH(C7,Categorías!$A$2:$A$18,0)),"") -> Ocio | E7: 3.5 | G7: =Categorías!A6 -> Viajes | H7: =SUMIF($C$3:$C$32,G7,$E$3:$E$32) -> 0 | I7: =Categorías!B6 -> Ocio
A8: 46210 | B8: bet | C8: Apuestas | D8: =IFERROR(INDEX(Categorías!$B$2:$B$18,MATCH(C8,Categorías!$A$2:$A$18,0)),"") -> Ocio | E8: 40 | G8: =Categorías!A7 -> Padel | H8: =SUMIF($C$3:$C$32,G8,$E$3:$E$32) -> 15.96 | I8: =Categorías!B7 -> Ocio
A9: 46213 | B9: Paki | C9: Alimentación | D9: =IFERROR(INDEX(Categorías!$B$2:$B$18,MATCH(C9,Categorías!$A$2:$A$18,0)),"") -> Ocio | E9: 5.5 | G9: =Categorías!A8 -> Alimentación | H9: =SUMIF($C$3:$C$32,G9,$E$3:$E$32) -> 14.8 | I9: =Categorías!B8 -> Ocio
A10: 46217 | B10: encuadernar tfg | C10: Burocracia | D10: =IFERROR(INDEX(Categorías!$B$2:$B$18,MATCH(C10,Categorías!$A$2:$A$18,0)),"") -> Extraordinario Inevitable | E10: 19.3 | G10: =Categorías!A9 -> Barça | H10: =SUMIF($C$3:$C$32,G10,$E$3:$E$32) -> 0 | I10: =Categorías!B9 -> Ocio
A11: 46218 | B11: McDonalds | C11: Alimentación | D11: =IFERROR(INDEX(Categorías!$B$2:$B$18,MATCH(C11,Categorías!$A$2:$A$18,0)),"") -> Ocio | E11: 4.5 | G11: =Categorías!A10 -> Vivienda/Alquiler | H11: =SUMIF($C$3:$C$32,G11,$E$3:$E$32) -> 0 | I11: =Categorías!B10 -> Ordinario
A12: 46222 | B12: Casa Rural | C12: Salidas/Ocio | D12: =IFERROR(INDEX(Categorías!$B$2:$B$18,MATCH(C12,Categorías!$A$2:$A$18,0)),"") -> Ocio | E12: 100 | G12: =Categorías!A11 -> Transporte | H12: =SUMIF($C$3:$C$32,G12,$E$3:$E$32) -> 0 | I12: =Categorías!B11 -> Ordinario
A13: 46225 | B13: Padel | C13: Padel | D13: =IFERROR(INDEX(Categorías!$B$2:$B$18,MATCH(C13,Categorías!$A$2:$A$18,0)),"") -> Ocio | E13: 3.5 | G13: =Categorías!A12 -> Salud | H13: =SUMIF($C$3:$C$32,G13,$E$3:$E$32) -> 0 | I13: =Categorías!B12 -> Ordinario
A14: 46226 | B14: Título uni | C14: Burocracia | D14: =IFERROR(INDEX(Categorías!$B$2:$B$18,MATCH(C14,Categorías!$A$2:$A$18,0)),"") -> Extraordinario Inevitable | E14: 218 | G14: =Categorías!A13 -> Barbero | H14: =SUMIF($C$3:$C$32,G14,$E$3:$E$32) -> 15 | I14: =Categorías!B13 -> Ordinario
A15: 46229 | B15: Cine+macdonalds | C15: Salidas/Ocio | D15: =IFERROR(INDEX(Categorías!$B$2:$B$18,MATCH(C15,Categorías!$A$2:$A$18,0)),"") -> Ocio | E15: =9.9+12.5 -> 22.4 | G15: =Categorías!A14 -> Otros | H15: =SUMIF($C$3:$C$32,G15,$E$3:$E$32) -> 0 | I15: =Categorías!B14 -> Ordinario
A16: 46231 | B16: Padel | C16: Padel | D16: =IFERROR(INDEX(Categorías!$B$2:$B$18,MATCH(C16,Categorías!$A$2:$A$18,0)),"") -> Ocio | E16: 3.5 | G16: =Categorías!A15 -> Burocracia | H16: =SUMIF($C$3:$C$32,G16,$E$3:$E$32) -> 237.3 | I16: =Categorías!B15 -> Extraordinario Inevitable
A17: 46232 | B17: EA FC | C17: Videojuegos | D17: =IFERROR(INDEX(Categorías!$B$2:$B$18,MATCH(C17,Categorías!$A$2:$A$18,0)),"") -> Ocio | E17: 40 | G17: =Categorías!A16 -> Regalos | H17: =SUMIF($C$3:$C$32,G17,$E$3:$E$32) -> 20 | I17: =Categorías!B16 -> Extraordinario Evitable
A18: 46233 | B18: Barbero | C18: Barbero | D18: =IFERROR(INDEX(Categorías!$B$2:$B$18,MATCH(C18,Categorías!$A$2:$A$18,0)),"") -> Ordinario | E18: 15 | G18: =Categorías!A17 -> Multas | H18: =SUMIF($C$3:$C$32,G18,$E$3:$E$32) -> 50 | I18: =Categorías!B17 -> Extraordinario Evitable
A19: 46233 | B19: Multa velocidad | C19: Multas | D19: =IFERROR(INDEX(Categorías!$B$2:$B$18,MATCH(C19,Categorías!$A$2:$A$18,0)),"") -> Extraordinario Evitable | E19: 50 | G19: =Categorías!A18 -> Otros extraordinarios | H19: =SUMIF($C$3:$C$32,G19,$E$3:$E$32) -> 0 | I19: =Categorías!B18 -> Extraordinario Inevitable
A20: 46221 | B20: Spotify | C20: Suscripciones ocio | D20: =IFERROR(INDEX(Categorías!$B$2:$B$18,MATCH(C20,Categorías!$A$2:$A$18,0)),"") -> Ocio | E20: 8.5
D21: =IFERROR(INDEX(Categorías!$B$2:$B$18,MATCH(C21,Categorías!$A$2:$A$18,0)),"") | G21: Total Ocio | H21: =SUMIF($I$3:$I$19,"Ocio",$H$3:$H$19) -> 241.66
D22: =IFERROR(INDEX(Categorías!$B$2:$B$18,MATCH(C22,Categorías!$A$2:$A$18,0)),"") | G22: Total Ordinario | H22: =SUMIF($I$3:$I$19,"Ordinario",$H$3:$H$19) -> 15
D23: =IFERROR(INDEX(Categorías!$B$2:$B$18,MATCH(C23,Categorías!$A$2:$A$18,0)),"") | G23: Total Extraordinario | H23: =SUMIF($I$3:$I$19,"Extraordinario*",$H$3:$H$19) -> 307.3
D24: =IFERROR(INDEX(Categorías!$B$2:$B$18,MATCH(C24,Categorías!$A$2:$A$18,0)),"") | G24: Total Extraordinario Evitable | H24: =SUMIF($I$3:$I$19,"Extraordinario Evitable",$H$3:$H$19) -> 70
D25: =IFERROR(INDEX(Categorías!$B$2:$B$18,MATCH(C25,Categorías!$A$2:$A$18,0)),"") | G25: Total Extraordinario Inevitable | H25: =SUMIF($I$3:$I$19,"Extraordinario Inevitable",$H$3:$H$19) -> 237.3
D26: =IFERROR(INDEX(Categorías!$B$2:$B$18,MATCH(C26,Categorías!$A$2:$A$18,0)),"") | G26: TOTAL MES | H26: =SUM($E$3:$E$32) -> 563.96
D27: =IFERROR(INDEX(Categorías!$B$2:$B$18,MATCH(C27,Categorías!$A$2:$A$18,0)),"")
D28: =IFERROR(INDEX(Categorías!$B$2:$B$18,MATCH(C28,Categorías!$A$2:$A$18,0)),"")
D29: =IFERROR(INDEX(Categorías!$B$2:$B$18,MATCH(C29,Categorías!$A$2:$A$18,0)),"")
D30: =IFERROR(INDEX(Categorías!$B$2:$B$18,MATCH(C30,Categorías!$A$2:$A$18,0)),"")
D31: =IFERROR(INDEX(Categorías!$B$2:$B$18,MATCH(C31,Categorías!$A$2:$A$18,0)),"")
D32: =IFERROR(INDEX(Categorías!$B$2:$B$18,MATCH(C32,Categorías!$A$2:$A$18,0)),"")

Sheet Agosto
A1: Gastos — Agosto 2026
A2: Fecha | B2: Descripción | C2: Categoría | D2: Tipo | E2: Importe | G2: Resumen del mes
A3: 46236 | B3: Monólogo+birras | C3: Salidas/Ocio | D3: =IFERROR(INDEX(Categorías!$B$2:$B$18,MATCH(C3,Categorías!$A$2:$A$18,0)),"") -> Ocio | E3: 15.6 | G3: =Categorías!A2 -> Videojuegos | H3: =SUMIF($C$3:$C$32,G3,$E$3:$E$32) -> 0 | I3: =Categorías!B2 -> Ocio
A4: 46235 | B4: Mascarilla | C4: Regalos | D4: =IFERROR(INDEX(Categorías!$B$2:$B$18,MATCH(C4,Categorías!$A$2:$A$18,0)),"") -> Extraordinario Evitable | E4: 6.35 | G4: =Categorías!A3 -> Apuestas | H4: =SUMIF($C$3:$C$32,G4,$E$3:$E$32) -> 0 | I4: =Categorías!B3 -> Ocio
A5: 46247 | B5: Cine | C5: Salidas/Ocio | D5: =IFERROR(INDEX(Categorías!$B$2:$B$18,MATCH(C5,Categorías!$A$2:$A$18,0)),"") -> Ocio | E5: =6.25+3.4 -> 9.65 | G5: =Categorías!A4 -> Salidas/Ocio | H5: =SUMIF($C$3:$C$32,G5,$E$3:$E$32) -> 25.25 | I5: =Categorías!B4 -> Ocio
A6: 46247 | B6: Spotify | C6: Suscripciones ocio | D6: =IFERROR(INDEX(Categorías!$B$2:$B$18,MATCH(C6,Categorías!$A$2:$A$18,0)),"") -> Ocio | E6: 8.5 | G6: =Categorías!A5 -> Suscripciones ocio | H6: =SUMIF($C$3:$C$32,G6,$E$3:$E$32) -> 11 | I6: =Categorías!B5 -> Ocio
A7: 46243 | B7: Mc Donalds | C7: Alimentación | D7: =IFERROR(INDEX(Categorías!$B$2:$B$18,MATCH(C7,Categorías!$A$2:$A$18,0)),"") -> Ocio | E7: 18 | G7: =Categorías!A6 -> Viajes | H7: =SUMIF($C$3:$C$32,G7,$E$3:$E$32) -> 0 | I7: =Categorías!B6 -> Ocio
A8: 46249 | B8: Padel | C8: Padel | D8: =IFERROR(INDEX(Categorías!$B$2:$B$18,MATCH(C8,Categorías!$A$2:$A$18,0)),"") -> Ocio | E8: 3.5 | G8: =Categorías!A7 -> Padel | H8: =SUMIF($C$3:$C$32,G8,$E$3:$E$32) -> 12.3 | I8: =Categorías!B7 -> Ocio
A9: 46253 | B9: Padel | C9: Padel | D9: =IFERROR(INDEX(Categorías!$B$2:$B$18,MATCH(C9,Categorías!$A$2:$A$18,0)),"") -> Ocio | E9: 3.5 | G9: =Categorías!A8 -> Alimentación | H9: =SUMIF($C$3:$C$32,G9,$E$3:$E$32) -> 21.6 | I9: =Categorías!B8 -> Ocio
A10: 46254 | B10: Crunchyroll | C10: Suscripciones ocio | D10: =IFERROR(INDEX(Categorías!$B$2:$B$18,MATCH(C10,Categorías!$A$2:$A$18,0)),"") -> Ocio | E10: 2.5 | G10: =Categorías!A9 -> Barça | H10: =SUMIF($C$3:$C$32,G10,$E$3:$E$32) -> 0 | I10: =Categorías!B9 -> Ocio
A11: 46260 | B11: Padel | C11: Padel | D11: =IFERROR(INDEX(Categorías!$B$2:$B$18,MATCH(C11,Categorías!$A$2:$A$18,0)),"") -> Ocio | E11: 5.3 | G11: =Categorías!A10 -> Vivienda/Alquiler | H11: =SUMIF($C$3:$C$32,G11,$E$3:$E$32) -> 0 | I11: =Categorías!B10 -> Ordinario
A12: 46262 | B12: Monsters | C12: Alimentación | D12: =IFERROR(INDEX(Categorías!$B$2:$B$18,MATCH(C12,Categorías!$A$2:$A$18,0)),"") -> Ocio | E12: 3.6 | G12: =Categorías!A11 -> Transporte | H12: =SUMIF($C$3:$C$32,G12,$E$3:$E$32) -> 0 | I12: =Categorías!B11 -> Ordinario
D13: =IFERROR(INDEX(Categorías!$B$2:$B$18,MATCH(C13,Categorías!$A$2:$A$18,0)),"") | G13: =Categorías!A12 -> Salud | H13: =SUMIF($C$3:$C$32,G13,$E$3:$E$32) -> 0 | I13: =Categorías!B12 -> Ordinario
D14: =IFERROR(INDEX(Categorías!$B$2:$B$18,MATCH(C14,Categorías!$A$2:$A$18,0)),"") | G14: =Categorías!A13 -> Barbero | H14: =SUMIF($C$3:$C$32,G14,$E$3:$E$32) -> 0 | I14: =Categorías!B13 -> Ordinario
D15: =IFERROR(INDEX(Categorías!$B$2:$B$18,MATCH(C15,Categorías!$A$2:$A$18,0)),"") | G15: =Categorías!A14 -> Otros | H15: =SUMIF($C$3:$C$32,G15,$E$3:$E$32) -> 0 | I15: =Categorías!B14 -> Ordinario
D16: =IFERROR(INDEX(Categorías!$B$2:$B$18,MATCH(C16,Categorías!$A$2:$A$18,0)),"") | G16: =Categorías!A15 -> Burocracia | H16: =SUMIF($C$3:$C$32,G16,$E$3:$E$32) -> 0 | I16: =Categorías!B15 -> Extraordinario Inevitable
D17: =IFERROR(INDEX(Categorías!$B$2:$B$18,MATCH(C17,Categorías!$A$2:$A$18,0)),"") | G17: =Categorías!A16 -> Regalos | H17: =SUMIF($C$3:$C$32,G17,$E$3:$E$32) -> 6.35 | I17: =Categorías!B16 -> Extraordinario Evitable
D18: =IFERROR(INDEX(Categorías!$B$2:$B$18,MATCH(C18,Categorías!$A$2:$A$18,0)),"") | G18: =Categorías!A17 -> Multas | H18: =SUMIF($C$3:$C$32,G18,$E$3:$E$32) -> 0 | I18: =Categorías!B17 -> Extraordinario Evitable
D19: =IFERROR(INDEX(Categorías!$B$2:$B$18,MATCH(C19,Categorías!$A$2:$A$18,0)),"") | G19: =Categorías!A18 -> Otros extraordinarios | H19: =SUMIF($C$3:$C$32,G19,$E$3:$E$32) -> 0 | I19: =Categorías!B18 -> Extraordinario Inevitable
D20: =IFERROR(INDEX(Categorías!$B$2:$B$18,MATCH(C20,Categorías!$A$2:$A$18,0)),"")
D21: =IFERROR(INDEX(Categorías!$B$2:$B$18,MATCH(C21,Categorías!$A$2:$A$18,0)),"") | G21: Total Ocio | H21: =SUMIF($I$3:$I$19,"Ocio",$H$3:$H$19) -> 70.15
D22: =IFERROR(INDEX(Categorías!$B$2:$B$18,MATCH(C22,Categorías!$A$2:$A$18,0)),"") | G22: Total Ordinario | H22: =SUMIF($I$3:$I$19,"Ordinario",$H$3:$H$19) -> 0
D23: =IFERROR(INDEX(Categorías!$B$2:$B$18,MATCH(C23,Categorías!$A$2:$A$18,0)),"") | G23: Total Extraordinario | H23: =SUMIF($I$3:$I$19,"Extraordinario*",$H$3:$H$19) -> 6.35
D24: =IFERROR(INDEX(Categorías!$B$2:$B$18,MATCH(C24,Categorías!$A$2:$A$18,0)),"") | G24: Total Extraordinario Evitable | H24: =SUMIF($I$3:$I$19,"Extraordinario Evitable",$H$3:$H$19) -> 6.35
D25: =IFERROR(INDEX(Categorías!$B$2:$B$18,MATCH(C25,Categorías!$A$2:$A$18,0)),"") | G25: Total Extraordinario Inevitable | H25: =SUMIF($I$3:$I$19,"Extraordinario Inevitable",$H$3:$H$19) -> 0
D26: =IFERROR(INDEX(Categorías!$B$2:$B$18,MATCH(C26,Categorías!$A$2:$A$18,0)),"") | G26: TOTAL MES | H26: =SUM($E$3:$E$32) -> 76.5
D27: =IFERROR(INDEX(Categorías!$B$2:$B$18,MATCH(C27,Categorías!$A$2:$A$18,0)),"")
D28: =IFERROR(INDEX(Categorías!$B$2:$B$18,MATCH(C28,Categorías!$A$2:$A$18,0)),"")
D29: =IFERROR(INDEX(Categorías!$B$2:$B$18,MATCH(C29,Categorías!$A$2:$A$18,0)),"")
D30: =IFERROR(INDEX(Categorías!$B$2:$B$18,MATCH(C30,Categorías!$A$2:$A$18,0)),"")
D31: =IFERROR(INDEX(Categorías!$B$2:$B$18,MATCH(C31,Categorías!$A$2:$A$18,0)),"")
D32: =IFERROR(INDEX(Categorías!$B$2:$B$18,MATCH(C32,Categorías!$A$2:$A$18,0)),"")

Sheet Septiembre
A1: Gastos — Septiembre 2026
A2: Fecha | B2: Descripción | C2: Categoría | D2: Tipo | E2: Importe | G2: Resumen del mes
A3: 46269 | B3: Desplazamiento Sevilla | C3: Barça | D3: =IFERROR(INDEX(Categorías!$B$2:$B$18,MATCH(C3,Categorías!$A$2:$A$18,0)),"") -> Ocio | E3: 97 | G3: =Categorías!A2 -> Videojuegos | H3: =SUMIF($C$3:$C$32,G3,$E$3:$E$32) -> 0 | I3: =Categorías!B2 -> Ocio
A4: 46269 | B4: Barça-Racing | C4: Barça | D4: =IFERROR(INDEX(Categorías!$B$2:$B$18,MATCH(C4,Categorías!$A$2:$A$18,0)),"") -> Ocio | E4: 100 | G4: =Categorías!A3 -> Apuestas | H4: =SUMIF($C$3:$C$32,G4,$E$3:$E$32) -> 0 | I4: =Categorías!B3 -> Ocio
A5: 46269 | B5: padel | C5: Padel | D5: =IFERROR(INDEX(Categorías!$B$2:$B$18,MATCH(C5,Categorías!$A$2:$A$18,0)),"") -> Ocio | E5: 3.5 | G5: =Categorías!A4 -> Salidas/Ocio | H5: =SUMIF($C$3:$C$32,G5,$E$3:$E$32) -> 12.5 | I5: =Categorías!B4 -> Ocio
A6: 46272 | B6: T-10 | C6: Transporte | D6: =IFERROR(INDEX(Categorías!$B$2:$B$18,MATCH(C6,Categorías!$A$2:$A$18,0)),"") -> Ordinario | E6: 13 | G6: =Categorías!A5 -> Suscripciones ocio | H6: =SUMIF($C$3:$C$32,G6,$E$3:$E$32) -> 8.5 | I6: =Categorías!B5 -> Ocio
A7: 46273 | B7: Padel | C7: Padel | D7: =IFERROR(INDEX(Categorías!$B$2:$B$18,MATCH(C7,Categorías!$A$2:$A$18,0)),"") -> Ocio | E7: 3.5 | G7: =Categorías!A6 -> Viajes | H7: =SUMIF($C$3:$C$32,G7,$E$3:$E$32) -> 0 | I7: =Categorías!B6 -> Ocio
A8: 46273 | B8: Monster | C8: Alimentación | D8: =IFERROR(INDEX(Categorías!$B$2:$B$18,MATCH(C8,Categorías!$A$2:$A$18,0)),"") -> Ocio | E8: 1.89 | G8: =Categorías!A7 -> Padel | H8: =SUMIF($C$3:$C$32,G8,$E$3:$E$32) -> 36.95 | I8: =Categorías!B7 -> Ocio
A9: 46275 | B9: Padel | C9: Padel | D9: =IFERROR(INDEX(Categorías!$B$2:$B$18,MATCH(C9,Categorías!$A$2:$A$18,0)),"") -> Ocio | E9: 5.5 | G9: =Categorías!A8 -> Alimentación | H9: =SUMIF($C$3:$C$32,G9,$E$3:$E$32) -> 1.89 | I9: =Categorías!B8 -> Ocio
A10: 46275 | B10: Barbero | C10: Barbero | D10: =IFERROR(INDEX(Categorías!$B$2:$B$18,MATCH(C10,Categorías!$A$2:$A$18,0)),"") -> Ordinario | E10: 15 | G10: =Categorías!A9 -> Barça | H10: =SUMIF($C$3:$C$32,G10,$E$3:$E$32) -> 197 | I10: =Categorías!B9 -> Ocio
A11: 46276 | B11: Padel | C11: Padel | D11: =IFERROR(INDEX(Categorías!$B$2:$B$18,MATCH(C11,Categorías!$A$2:$A$18,0)),"") -> Ocio | E11: 4.5 | G11: =Categorías!A10 -> Vivienda/Alquiler | H11: =SUMIF($C$3:$C$32,G11,$E$3:$E$32) -> 0 | I11: =Categorías!B10 -> Ordinario
A12: 46276 | B12: Spotify | C12: Suscripciones ocio | D12: =IFERROR(INDEX(Categorías!$B$2:$B$18,MATCH(C12,Categorías!$A$2:$A$18,0)),"") -> Ocio | E12: 8.5 | G12: =Categorías!A11 -> Transporte | H12: =SUMIF($C$3:$C$32,G12,$E$3:$E$32) -> 13 | I12: =Categorías!B11 -> Ordinario
A13: 46276 | B13: Padel Pro League | C13: Padel | D13: =IFERROR(INDEX(Categorías!$B$2:$B$18,MATCH(C13,Categorías!$A$2:$A$18,0)),"") -> Ocio | E13: 19.95 | G13: =Categorías!A12 -> Salud | H13: =SUMIF($C$3:$C$32,G13,$E$3:$E$32) -> 0 | I13: =Categorías!B12 -> Ordinario
A14: 46276 | B14: Karting+mcd | C14: Salidas/ocio | D14: =IFERROR(INDEX(Categorías!$B$2:$B$18,MATCH(C14,Categorías!$A$2:$A$18,0)),"") -> Ocio | E14: 12.5 | G14: =Categorías!A13 -> Barbero | H14: =SUMIF($C$3:$C$32,G14,$E$3:$E$32) -> 15 | I14: =Categorías!B13 -> Ordinario
D15: =IFERROR(INDEX(Categorías!$B$2:$B$18,MATCH(C15,Categorías!$A$2:$A$18,0)),"") | G15: =Categorías!A14 -> Otros | H15: =SUMIF($C$3:$C$32,G15,$E$3:$E$32) -> 0 | I15: =Categorías!B14 -> Ordinario
D16: =IFERROR(INDEX(Categorías!$B$2:$B$18,MATCH(C16,Categorías!$A$2:$A$18,0)),"") | G16: =Categorías!A15 -> Burocracia | H16: =SUMIF($C$3:$C$32,G16,$E$3:$E$32) -> 0 | I16: =Categorías!B15 -> Extraordinario Inevitable
D17: =IFERROR(INDEX(Categorías!$B$2:$B$18,MATCH(C17,Categorías!$A$2:$A$18,0)),"") | G17: =Categorías!A16 -> Regalos | H17: =SUMIF($C$3:$C$32,G17,$E$3:$E$32) -> 0 | I17: =Categorías!B16 -> Extraordinario Evitable
D18: =IFERROR(INDEX(Categorías!$B$2:$B$18,MATCH(C18,Categorías!$A$2:$A$18,0)),"") | G18: =Categorías!A17 -> Multas | H18: =SUMIF($C$3:$C$32,G18,$E$3:$E$32) -> 0 | I18: =Categorías!B17 -> Extraordinario Evitable
D19: =IFERROR(INDEX(Categorías!$B$2:$B$18,MATCH(C19,Categorías!$A$2:$A$18,0)),"") | G19: =Categorías!A18 -> Otros extraordinarios | H19: =SUMIF($C$3:$C$32,G19,$E$3:$E$32) -> 0 | I19: =Categorías!B18 -> Extraordinario Inevitable
D20: =IFERROR(INDEX(Categorías!$B$2:$B$18,MATCH(C20,Categorías!$A$2:$A$18,0)),"")
D21: =IFERROR(INDEX(Categorías!$B$2:$B$18,MATCH(C21,Categorías!$A$2:$A$18,0)),"") | G21: Total Ocio | H21: =SUMIF($I$3:$I$19,"Ocio",$H$3:$H$19) -> 256.84
D22: =IFERROR(INDEX(Categorías!$B$2:$B$18,MATCH(C22,Categorías!$A$2:$A$18,0)),"") | G22: Total Ordinario | H22: =SUMIF($I$3:$I$19,"Ordinario",$H$3:$H$19) -> 28
D23: =IFERROR(INDEX(Categorías!$B$2:$B$18,MATCH(C23,Categorías!$A$2:$A$18,0)),"") | G23: Total Extraordinario | H23: =SUMIF($I$3:$I$19,"Extraordinario*",$H$3:$H$19) -> 0
D24: =IFERROR(INDEX(Categorías!$B$2:$B$18,MATCH(C24,Categorías!$A$2:$A$18,0)),"") | G24: Total Extraordinario Evitable | H24: =SUMIF($I$3:$I$19,"Extraordinario Evitable",$H$3:$H$19) -> 0
D25: =IFERROR(INDEX(Categorías!$B$2:$B$18,MATCH(C25,Categorías!$A$2:$A$18,0)),"") | G25: Total Extraordinario Inevitable | H25: =SUMIF($I$3:$I$19,"Extraordinario Inevitable",$H$3:$H$19) -> 0
D26: =IFERROR(INDEX(Categorías!$B$2:$B$18,MATCH(C26,Categorías!$A$2:$A$18,0)),"") | G26: TOTAL MES | H26: =SUM($E$3:$E$32) -> 284.84
D27: =IFERROR(INDEX(Categorías!$B$2:$B$18,MATCH(C27,Categorías!$A$2:$A$18,0)),"")
D28: =IFERROR(INDEX(Categorías!$B$2:$B$18,MATCH(C28,Categorías!$A$2:$A$18,0)),"")
D29: =IFERROR(INDEX(Categorías!$B$2:$B$18,MATCH(C29,Categorías!$A$2:$A$18,0)),"")
